Workbook

Sheet DATASHEET
A1: Browse Study Data | C1: = Changed in office. | E1: = question
A2: Site Info | F2: Initial Measurements | I2: 1-Week Measurments | M2: 2-Month Measurements | R2: 4-Month Measurements | X2: 6-Month Measurements | AB2: 12-Month Measurements
A3: REP | B3: ROW | C3: TREAT_NAME | D3: TREE_NMBR | E3: SPECIES | F3: DATE | G3: HT | H3: DIAM | I3: DATE | J3: BROWSE Y/N | K3: MORT Y/N | L3: HT | M3: DATE | N3: BROWSE Y/N | O3: MORT Y/N | P3: VEXAR DAMAGE/FAILURE | Q3: HT | R3: DATE | S3: BROWSE Y/N | T3: MORT Y/N | U3: VEXAR DAMAGE/FAILURE | V3: HT | W3: DIAM | X3: DATE | Y3: BROWSE Y/N | Z3: MORT Y/N | AA3: HT | AB3: DATE | AC3: BROWSE Y/N | AD3: MORT Y/N | AE3: HT
A4: HUMANN RESOURCES 2010 | B4: A | C4: SS CTRL | D4: 1 | E4: SS | F4: 42101 | G4: 45.72 | H4: 5.08 | I4: 42117 | M4: 42157 | Q4: 54.864 | R4: 42233 | V4: 66 | W4: 5.16
A5: HUMANN RESOURCES 2010 | B5: A | C5: SS CTRL | D5: 2 | E5: SS | F5: 42101 | G5: 44.196 | H5: 3.048 | I5: 42117 | M5: 42157 | Q5: 53.086 | R5: 42233 | T5: Y | V5: 62 | W5: 4.91
A6: HUMANN RESOURCES 2010 | B6: A | C6: SS CTRL | D6: 3 | E6: SS | F6: 42101 | G6: 38.608 | H6: 4.064 | I6: 42117 | M6: 42157 | Q6: 46.736 | R6: 42233 | T6: Y | V6: 51 | W6: 5.48
A7: HUMANN RESOURCES 2010 | B7: A | C7: SS CTRL | D7: 4 | E7: SS | F7: 42101 | G7: 46.736 | H7: 4.826 | I7: 42117 | M7: 42157 | Q7: 55.88 | R7: 42233 | V7: 66.8 | W7: 6.95
A8: HUMANN RESOURCES 2010 | B8: A | C8: SS CTRL | D8: 5 | E8: SS | F8: 42101 | G8: 49.022 | H8: 4.826 | I8: 42117 | M8: 42157 | Q8: 49.784 | R8: 42233 | T8: Y | V8: 53 | W8: 5.87
A9: HUMANN RESOURCES 2010 | B9: A | C9: SS CTRL | D9: 6 | E9: SS | F9: 42101 | G9: 33.02 | H9: 4.572 | I9: 42117 | M9: 42157 | Q9: 38.354 | R9: 42233 | T9: Y | V9: 43 | W9: 6.22
A10: HUMANN RESOURCES 2010 | B10: A | C10: SS CTRL | D10: 7 | E10: SS | F10: 42101 | G10: 45.72 | H10: 3.81 | I10: 42117 | M10: 42157 | Q10: 54.61 | R10: 42233 | T10: Y | V10: 60.5 | W10: 6.12
A11: HUMANN RESOURCES 2010 | B11: A | C11: SS CTRL | D11: 8 | E11: SS | F11: 42101 | G11: 39.878 | H11: 3.81 | I11: 42117 | M11: 42157 | Q11: 43.18 | R11: 42233 | T11: Y | V11: 48 | W11: 5.63
A12: HUMANN RESOURCES 2010 | B12: A | C12: SS CTRL | D12: 9 | E12: SS | F12: 42101 | G12: 40.894 | H12: 4.318 | I12: 42117 | M12: 42157 | Q12: 51.308 | R12: 42233 | T12: Y | V12: 58 | W12: 5.03
A13: HUMANN RESOURCES 2010 | B13: A | C13: SS CTRL | D13: 10 | E13: SS | F13: 42101 | G13: 40.894 | H13: 4.572 | I13: 42117 | M13: 42157 | Q13: 48.006 | R13: 42233 | T13: Y | V13: 54 | W13: 4.26
A14: HUMANN RESOURCES 2010 | B14: A | C14: SS CTRL | D14: 11 | E14: SS | F14: 42101 | G14: 38.608 | H14: 4.064 | I14: 42117 | M14: 42157 | Q14: 52.832 | R14: 42233 | V14: 63 | W14: 5.34
A15: HUMANN RESOURCES 2010 | B15: A | C15: SS CTRL | D15: 12 | E15: SS | F15: 42101 | G15: 38.862 | H15: 4.826 | I15: 42117 | M15: 42157 | Q15: 46.228 | R15: 42233 | T15: Y | V15: 55 | W15: 5.26
A16: HUMANN RESOURCES 2010 | B16: A | C16: SS CTRL | D16: 13 | E16: SS | F16: 42101 | G16: 36.576 | H16: 3.302 | I16: 42117 | M16: 42157 | Q16: 46.736 | R16: 42233 | T16: Y | V16: 56 | W16: 4.38
A17: HUMANN RESOURCES 2010 | B17: A | C17: SS CTRL | D17: 14 | E17: SS | F17: 42101 | G17: 39.116 | H17: 4.826 | I17: 42117 | M17: 42157 | Q17: 52.07 | R17: 42233 | T17: Y | V17: 59 | W17: 5.31
A18: HUMANN RESOURCES 2010 | B18: A | C18: SS CTRL | D18: 15 | E18: SS | F18: 42101 | G18: 39.878 | H18: 4.318 | I18: 42117 | M18: 42157 | Q18: 49.276 | R18: 42233 | T18: Y | V18: 54 | W18: 5.1
A19: HUMANN RESOURCES 2010 | B19: A | C19: SS CTRL | D19: 16 | E19: SS | F19: 42101 | G19: 38.608 | H19: 4.318 | I19: 42117 | M19: 42157 | Q19: 39.37 | R19: 42233 | V19: 44 | W19: 5.37
A20: HUMANN RESOURCES 2010 | B20: A | C20: SS CTRL | D20: 17 | E20: SS | F20: 42101 | G20: 38.862 | H20: 4.572 | I20: 42117 | M20: 42157 | Q20: 48.061118 | R20: 42233 | T20: Y | V20: 56 | W20: 5.35
A21: HUMANN RESOURCES 2010 | B21: A | C21: SS CTRL | D21: 18 | E21: SS | F21: 42101 | G21: 38.354 | H21: 4.572 | I21: 42117 | M21: 42157 | Q21: 54.61 | R21: 42233 | T21: Y | V21: 64 | W21: 5.59
A22: HUMANN RESOURCES 2010 | B22: A | C22: SS CTRL | D22: 19 | E22: SS | F22: 42101 | G22: 45.72 | H22: 4.826 | I22: 42117 | M22: 42157 | Q22: 56.134 | R22: 42233 | T22: Y | V22: 63 | W22: 5.12
A23: HUMANN RESOURCES 2010 | B23: A | C23: SS CTRL | D23: 20 | E23: SS | F23: 42101 | G23: 43.18 | H23: 4.318 | I23: 42117 | M23: 42157 | Q23: 55.88 | R23: 42233 | T23: Y | V23: 59 | W23: 4.63
A24: HUMANN RESOURCES 2010 | B24: B | C24: PLANTSKYDD | D24: 1 | E24: WRC | F24: 42101 | G24: 40.64 | H24: 5.08 | I24: 42117 | M24: 42157 | Q24: 45.466 | R24: 42233 | S24: Y | T24: Y | V24: 52 | W24: 5.8
A25: HUMANN RESOURCES 2010 | B25: B | C25: PLANTSKYDD | D25: 2 | E25: WRC | F25: 42101 | G25: 25.4 | H25: 2.794 | I25: 42117 | M25: 42157 | O25: Y | Q25: 20.574 | R25: 42233 | S25: Y | T25: Y | V25: 23 | W25: 1.89
A26: HUMANN RESOURCES 2010 | B26: B | C26: PLANTSKYDD | D26: 3 | E26: WRC | F26: 42101 | G26: 20.32 | H26: 2.286 | I26: 42117 | M26: 42157 | Q26: 20.828 | R26: 42233 | T26: Y | V26: 20.5 | W26: 2.66
A27: HUMANN RESOURCES 2010 | B27: B | C27: PLANTSKYDD | D27: 4 | E27: WRC | F27: 42101 | G27: 27.94 | H27: 3.302 | I27: 42117 | M27: 42157 | Q27: 33.274 | R27: 42233 | S27: Y | T27: Y | V27: 23 | W27: 2.06
A28: HUMANN RESOURCES 2010 | B28: B | C28: PLANTSKYDD | D28: 5 | E28: WRC | F28: 42101 | G28: 33.02 | H28: 3.302 | I28: 42117 | M28: 42157 | Q28: 44.45 | R28: 42233 | T28: Y | V28: 47 | W28: 4.88
A29: HUMANN RESOURCES 2010 | B29: B | C29: PLANTSKYDD | D29: 6 | E29: WRC | F29: 42101 | G29: 26.416 | H29: 4.064 | I29: 42117 | M29: 42157 | Q29: 38.354 | R29: 42233 | T29: Y | V29: 42.5 | W29: 5.33
A30: HUMANN RESOURCES 2010 | B30: B | C30: PLANTSKYDD | D30: 7 | E30: WRC | F30: 42101 | G30: 35.56 | H30: 5.08 | I30: 42117 | M30: 42157 | Q30: 45.974 | R30: 42233 | T30: Y | V30: 53 | W30: 5.29
A31: HUMANN RESOURCES 2010 | B31: B | C31: PLANTSKYDD | D31: 8 | E31: WRC | F31: 42101 | G31: 34.798 | H31: 5.08 | I31: 42117 | M31: 42157 | Q31: 48.006 | R31: 42233 | T31: Y | V31: 51 | W31: 5.77
A32: HUMANN RESOURCES 2010 | B32: B | C32: PLANTSKYDD | D32: 9 | E32: WRC | F32: 42101 | G32: 48.26 | H32: 4.318 | I32: 42117 | M32: 42157 | Q32: 51.054 | R32: 42233 | T32: Y | V32: 54 | W32: 6.81
A33: HUMANN RESOURCES 2010 | B33: B | C33: PLANTSKYDD | D33: 10 | E33: WRC | F33: 42101 | G33: 27.94 | H33: 2.032 | I33: 42117 | M33: 42157 | Q33: 33.02 | R33: 42233 | T33: Y
A34: HUMANN RESOURCES 2010 | B34: B | C34: PLANTSKYDD | D34: 11 | E34: WRC | F34: 42101 | G34: 27.94 | H34: 4.572 | I34: 42117 | M34: 42157 | Q34: 38.608 | R34: 42233 | T34: Y | V34: 42 | W34: 3.79
A35: HUMANN RESOURCES 2010 | B35: B | C35: PLANTSKYDD | D35: 12 | E35: WRC | F35: 42101 | G35: 27.94 | H35: 3.302 | I35: 42117 | M35: 42157 | Q35: 40.386 | R35: 42233 | T35: Y | V35: 44 | W35: 4.76
A36: HUMANN RESOURCES 2010 | B36: B | C36: PLANTSKYDD | D36: 13 | E36: WRC | F36: 42101 | G36: 28.956 | H36: 3.302 | I36: 42117 | M36: 42157 | Q36: 40.894 | R36: 42233 | T36: Y | V36: 45 | W36: 4.97
A37: HUMANN RESOURCES 2010 | B37: B | C37: PLANTSKYDD | D37: 14 | E37: WRC | F37: 42101 | G37: 24.638 | H37: 2.286 | I37: 42117 | M37: 42157 | Q37: 23.368 | R37: 42233 | T37: Y | V37: 46 | W37: 3.89
A38: HUMANN RESOURCES 2010 | B38: B | C38: PLANTSKYDD | D38: 15 | E38: WRC | F38: 42101 | G38: 25.4 | H38: 2.286 | I38: 42117 | M38: 42157 | Q38: 27.686 | R38: 42233 | T38: Y | V38: 30.5 | W38: 3.29
A39: HUMANN RESOURCES 2010 | B39: B | C39: PLANTSKYDD | D39: 16 | E39: WRC | F39: 42101 | G39: 27.178 | H39: 3.302 | I39: 42117 | M39: 42157 | Q39: 31.242 | R39: 42233 | T39: Y
A40: HUMANN RESOURCES 2010 | B40: B | C40: PLANTSKYDD | D40: 17 | E40: WRC | F40: 42101 | G40: 22.86 | H40: 2.286 | I40: 42117 | M40: 42157 | Q40: 25.4 | R40: 42233 | T40: Y | V40: 26 | W40: 4.63
...

Sheet FEEDER
A1: =IF(DATASHEET!A2=0,"",DATASHEET!A2) -> Site Info | B1: =IF(DATASHEET!B2=0,"",DATASHEET!B2) | C1: =IF(DATASHEET!C2=0,"",DATASHEET!C2) | E1: =IF(DATASHEET!D2=0,"",DATASHEET!D2) | F1: =IF(DATASHEET!E2=0,"",DATASHEET!E2) | G1: =IF(DATASHEET!F2=0,"",DATASHEET!F2) -> Initial Measurements | H1: =IF(DATASHEET!G2=0,"",DATASHEET!G2) | I1: =IF(DATASHEET!H2=0,"",DATASHEET!H2) | J1: =IF(DATASHEET!I2=0,"",DATASHEET!I2) -> 1-Week Measurments | K1: =IF(DATASHEET!J2=0,"",DATASHEET!J2) | L1: =IF(DATASHEET!K2=0,"",DATASHEET!K2) | M1: =IF(DATASHEET!L2=0,"",DATASHEET!L2) | T1: =IF(DATASHEET!M2=0,"",DATASHEET!M2) -> 2-Month Measurements | U1: =IF(DATASHEET!N2=0,"",DATASHEET!N2) | V1: =IF(DATASHEET!O2=0,"",DATASHEET!O2) | W1: =IF(DATASHEET!Q2=0,"",DATASHEET!Q2) | AD1: =IF(DATASHEET!R2=0,"",DATASHEET!R2) -> 4-Month Measurements | AE1: =IF(DATASHEET!S2=0,"",DATASHEET!S2) | AF1: =IF(DATASHEET!T2=0,"",DATASHEET!T2) | AG1: =IF(DATASHEET!V2=0,"",DATASHEET!V2) | AN1: =IF(DATASHEET!X2=0,"",DATASHEET!X2) -> 6-Month Measurements | AO1: =IF(DATASHEET!Y2=0,"",DATASHEET!Y2) | AP1: =IF(DATASHEET!Z2=0,"",DATASHEET!Z2) | AQ1: =IF(DATASHEET!AA2=0,"",DATASHEET!AA2) | AR1: =IF(DATASHEET!AB2=0,"",DATASHEET!AB2) -> 12-Month Measurements | AS1: =IF(DATASHEET!AC2=0,"",DATASHEET!AC2) | AT1: =IF(DATASHEET!AD2=0,"",DATASHEET!AD2) | AU1: =IF(DATASHEET!AE2=0,"",DATASHEET!AE2)
A2: =IF(DATASHEET!A3=0,"",DATASHEET!A3) -> REP | B2: =IF(DATASHEET!B3=0,"",DATASHEET!B3) -> ROW | C2: =IF(DATASHEET!C3=0,"",DATASHEET!C3) -> TREAT_NAME | D2: CONCATENATE TREATMENT | E2: =IF(DATASHEET!D3=0,"",DATASHEET!D3) -> TREE_NMBR | F2: =IF(DATASHEET!E3=0,"",DATASHEET!E3) -> SPECIES | G2: =IF(DATASHEET!F3=0,"",DATASHEET!F3) -> DATE | H2: =IF(DATASHEET!G3=0,"",DATASHEET!G3) -> HT | I2: =IF(DATASHEET!H3=0,"",DATASHEET!H3) -> DIAM | J2: =IF(DATASHEET!I3=0,"",DATASHEET!I3) -> DATE | K2: =IF(DATASHEET!J3=0,"",DATASHEET!J3) -> BROWSE Y/N | L2: =IF(DATASHEET!K3=0,"",DATASHEET!K3) -> MORT Y/N | M2: =IF(DATASHEET!L3=0,"",DATASHEET!L3) -> HT | N2: TIME SINCE INITIAL (Days) | O2: INITIAL & CURRENT HEIGHT | P2: BROWSE LOSS | Q2: INITIAL COUNT | R2: BROWSE FREQUENCY | S2: MORTALITY COUNT | T2: =IF(DATASHEET!M3=0,"",DATASHEET!M3) -> DATE | U2: =IF(DATASHEET!N3=0,"",DATASHEET!N3) -> BROWSE Y/N | V2: =IF(DATASHEET!O3=0,"",DATASHEET!O3) -> MORT Y/N | W2: =IF(DATASHEET!Q3=0,"",DATASHEET!Q3) -> HT | X2: TIME SINCE INITIAL (Days) | Y2: CURRENT HEIGHT | Z2: BROWSE LOSS | AA2: INITIAL COUNT | AB2: BROWSE FREQUENCY | AC2: MORTALITY COUNT | AD2: =IF(DATASHEET!R3=0,"",DATASHEET!R3) -> DATE | AE2: =IF(DATASHEET!S3=0,"",DATASHEET!S3) -> BROWSE Y/N | AF2: =IF(DATASHEET!T3=0,"",DATASHEET!T3) -> MORT Y/N | AG2: =IF(DATASHEET!V3=0,"",DATASHEET!V3) -> HT | AH2: TIME SINCE INITIAL (Days) | AI2: CURRENT HEIGHT | AJ2: BROWSE LOSS | AK2: INITIAL COUNT | AL2: BROWSE FREQUENCY | AM2: MORTALITY COUNT | AN2: =IF(DATASHEET!X3=0,"",DATASHEET!X3) -> DATE | AO2: =IF(DATASHEET!Y3=0,"",DATASHEET!Y3) -> BROWSE Y/N | AP2: =IF(DATASHEET!Z3=0,"",DATASHEET!Z3) -> MORT Y/N | AQ2: =IF(DATASHEET!AA3=0,"",DATASHEET!AA3) -> HT | AR2: =IF(DATASHEET!AB3=0,"",DATASHEET!AB3) -> DATE | AS2: =IF(DATASHEET!AC3=0,"",DATASHEET!AC3) -> BROWSE Y/N | AT2: =IF(DATASHEET!AD3=0,"",DATASHEET!AD3) -> MORT Y/N | AU2: =IF(DATASHEET!AE3=0,"",DATASHEET!AE3) -> HT
A3: =IF(DATASHEET!A4=0,"",DATASHEET!A4) -> HUMANN RESOURCES 2010 | B3: =IF(DATASHEET!B4=0,"",DATASHEET!B4) -> A | C3: =IF(DATASHEET!C4=0,"",DATASHEET!C4) -> SS CTRL | D3: =IF(C3="CO-PLANTING",CONCATENATE(C3," ",F3),C3) -> SS CTRL | E3: =IF(DATASHEET!D4=0,"",DATASHEET!D4) -> 1 | F3: =IF(DATASHEET!E4=0,"",DATASHEET!E4) -> SS | G3: =IF(DATASHEET!F4=0,"",DATASHEET!F4) -> 42101 | H3: =IF(DATASHEET!G4=0,"",DATASHEET!G4) -> 45.72 | I3: =IF(DATASHEET!H4=0,"",DATASHEET!H4) -> 5.08 | J3: =IF(DATASHEET!I4=0,"",DATASHEET!I4) -> 42117 | K3: =IF(DATASHEET!J4=0,"",DATASHEET!J4) | L3: =IF(DATASHEET!K4=0,"",DATASHEET!K4) | M3: =IF(DATASHEET!L4=0,"",DATASHEET!L4) | N3: =J3-$G3 -> 16 | O3: =IF(M3="",$H3,M3) -> 45.72 | P3: =IF(ISERROR($H3-M3),0,ABS($H3-M3)) -> 0 | Q3: 1 | R3: =IF(K3="Y",1,0) -> 0 | S3: =IF(L3="Y",1,0) -> 0 | T3: =IF(DATASHEET!M4=0,"",DATASHEET!M4) -> 42157 | U3: =IF(DATASHEET!N4=0,"",DATASHEET!N4) | V3: =IF(DATASHEET!O4=0,"",DATASHEET!O4) | W3: =IF(DATASHEET!Q4=0,"",DATASHEET!Q4) -> 54.864 | X3: =T3-$G3 -> 56 | Y3: =W3 -> 54.864 | Z3: =IF(AND($H3-W3>0,U3="Y"),ABS($H3-W3),0) -> 0 | AA3: 1 | AB3: =IF(U3="Y",1,0) -> 0 | AC3: =IF(V3="Y",1,0) -> 0 | AD3: =IF(DATASHEET!R4=0,"",DATASHEET!R4) -> 42233 | AE3: =IF(DATASHEET!S4=0,"",DATASHEET!S4) | AF3: =IF(DATASHEET!T4=0,"",DATASHEET!T4) | AG3: =IF(DATASHEET!V4=0,"",DATASHEET!V4) -> 66 | AH3: =AD3-$G3 -> 132 | AI3: =AG3 -> 66 | AJ3: =IF(AND($W3-AG3>0,AE3="Y"),ABS($W3-AG3),0) -> 0 | AK3: 1 | AL3: =IF(AE3="Y",1,0) -> 0 | AM3: =IF(AF3="Y",1,0) -> 0 | AN3: =IF(DATASHEET!X4=0,"",DATASHEET!X4) | AO3: =IF(DATASHEET!Y4=0,"",DATASHEET!Y4) | AP3: =IF(DATASHEET!Z4=0,"",DATASHEET!Z4) | AQ3: =IF(DATASHEET!AA4=0,"",DATASHEET!AA4) | AR3: =IF(DATASHEET!AB4=0,"",DATASHEET!AB4) | AS3: =IF(DATASHEET!AC4=0,"",DATASHEET!AC4) | AT3: =IF(DATASHEET!AD4=0,"",DATASHEET!AD4) | AU3: =IF(DATASHEET!AE4=0,"",DATASHEET!AE4)
A4: =IF(DATASHEET!A5=0,"",DATASHEET!A5) -> HUMANN RESOURCES 2010 | B4: =IF(DATASHEET!B5=0,"",DATASHEET!B5) -> A | C4: =IF(DATASHEET!C5=0,"",DATASHEET!C5) -> SS CTRL | D4: =IF(C4="CO-PLANTING",CONCATENATE(C4," ",F4),C4) -> SS CTRL | E4: =IF(DATASHEET!D5=0,"",DATASHEET!D5) -> 2 | F4: =IF(DATASHEET!E5=0,"",DATASHEET!E5) -> SS | G4: =IF(DATASHEET!F5=0,"",DATASHEET!F5) -> 42101 | H4: =IF(DATASHEET!G5=0,"",DATASHEET!G5) -> 44.196 | I4: =IF(DATASHEET!H5=0,"",DATASHEET!H5) -> 3.048 | J4: =IF(DATASHEET!I5=0,"",DATASHEET!I5) -> 42117 | K4: =IF(DATASHEET!J5=0,"",DATASHEET!J5) | L4: =IF(DATASHEET!K5=0,"",DATASHEET!K5) | M4: =IF(DATASHEET!L5=0,"",DATASHEET!L5) | N4: =J4-G4 -> 16 | O4: =IF(M4="",$H4,M4) -> 44.196 | P4: =IF(ISERROR($H4-M4),0,ABS($H4-M4)) -> 0 | Q4: 1 | R4: =IF(K4="Y",1,0) -> 0 | S4: =IF(L4="Y",1,0) -> 0 | T4: =IF(DATASHEET!M5=0,"",DATASHEET!M5) -> 42157 | V4: =IF(DATASHEET!O5=0,"",DATASHEET!O5) | W4: =IF(DATASHEET!Q5=0,"",DATASHEET!Q5) -> 53.086 | X4: =T4-$G4 -> 56 | Y4: =W4 -> 53.086 | Z4: =IF(AND($H4-W4>0,U4="Y"),ABS($H4-W4),0) -> 0 | AA4: 1 | AB4: =IF(U4="Y",1,0) -> 0 | AC4: =IF(V4="Y",1,0) -> 0 | AD4: =IF(DATASHEET!R5=0,"",DATASHEET!R5) -> 42233 | AE4: =IF(DATASHEET!S5=0,"",DATASHEET!S5) | AF4: =IF(DATASHEET!T5=0,"",DATASHEET!T5) -> Y | AG4: =IF(DATASHEET!V5=0,"",DATASHEET!V5) -> 62 | AH4: =AD4-$G4 -> 132 | AI4: =AG4 -> 62 | AJ4: =IF(AND($W4-AG4>0,AE4="Y"),ABS($W4-AG4),0) -> 0 | AK4: 1 | AL4: =IF(AE4="Y",1,0) -> 0 | AM4: =IF(AF4="Y",1,0) -> 1 | AN4: =IF(DATASHEET!X5=0,"",DATASHEET!X5) | AO4: =IF(DATASHEET!Y5=0,"",DATASHEET!Y5) | AP4: =IF(DATASHEET!Z5=0,"",DATASHEET!Z5) | AQ4: =IF(DATASHEET!AA5=0,"",DATASHEET!AA5) | AR4: =IF(DATASHEET!AB5=0,"",DATASHEET!AB5) | AS4: =IF(DATASHEET!AC5=0,"",DATASHEET!AC5) | AT4: =IF(DATASHEET!AD5=0,"",DATASHEET!AD5) | AU4: =IF(DATASHEET!AE5=0,"",DATASHEET!AE5)
A5: =IF(DATASHEET!A6=0,"",DATASHEET!A6) -> HUMANN RESOURCES 2010 | B5: =IF(DATASHEET!B6=0,"",DATASHEET!B6) -> A | C5: =IF(DATASHEET!C6=0,"",DATASHEET!C6) -> SS CTRL | D5: =IF(C5="CO-PLANTING",CONCATENATE(C5," ",F5),C5) -> SS CTRL | E5: =IF(DATASHEET!D6=0,"",DATASHEET!D6) -> 3 | F5: =IF(DATASHEET!E6=0,"",DATASHEET!E6) -> SS | G5: =IF(DATASHEET!F6=0,"",DATASHEET!F6) -> 42101 | H5: =IF(DATASHEET!G6=0,"",DATASHEET!G6) -> 38.608 | I5: =IF(DATASHEET!H6=0,"",DATASHEET!H6) -> 4.064 | J5: =IF(DATASHEET!I6=0,"",DATASHEET!I6) -> 42117 | K5: =IF(DATASHEET!J6=0,"",DATASHEET!J6) | L5: =IF(DATASHEET!K6=0,"",DATASHEET!K6) | M5: =IF(DATASHEET!L6=0,"",DATASHEET!L6) | N5: =J5-G5 -> 16 | O5: =IF(M5="",$H5,M5) -> 38.608 | P5: =IF(ISERROR($H5-M5),0,ABS($H5-M5)) -> 0 | Q5: 1 | R5: =IF(K5="Y",1,0) -> 0 | S5: =IF(L5="Y",1,0) -> 0 | T5: =IF(DATASHEET!M6=0,"",DATASHEET!M6) -> 42157 | U5: =IF(DATASHEET!N6=0,"",DATASHEET!N6) | V5: =IF(DATASHEET!O6=0,"",DATASHEET!O6) | W5: =IF(DATASHEET!Q6=0,"",DATASHEET!Q6) -> 46.736 | X5: =T5-$G5 -> 56 | Y5: =W5 -> 46.736 | Z5: =IF(AND($H5-W5>0,U5="Y"),ABS($H5-W5),0) -> 0 | AA5: 1 | AB5: =IF(U5="Y",1,0) -> 0 | AC5: =IF(V5="Y",1,0) -> 0 | AD5: =IF(DATASHEET!R6=0,"",DATASHEET!R6) -> 42233 | AE5: =IF(DATASHEET!S6=0,"",DATASHEET!S6) | AF5: =IF(DATASHEET!T6=0,"",DATASHEET!T6) -> Y | AG5: =IF(DATASHEET!V6=0,"",DATASHEET!V6) -> 51 | AH5: =AD5-$G5 -> 132 | AI5: =AG5 -> 51 | AJ5: =IF(AND($W5-AG5>0,AE5="Y"),ABS($W5-AG5),0) -> 0 | AK5: 1 | AL5: =IF(AE5="Y",1,0) -> 0 | AM5: =IF(AF5="Y",1,0) -> 1 | AN5: =IF(DATASHEET!X6=0,"",DATASHEET!X6) | AO5: =IF(DATASHEET!Y6=0,"",DATASHEET!Y6) | AP5: =IF(DATASHEET!Z6=0,"",DATASHEET!Z6) | AQ5: =IF(DATASHEET!AA6=0,"",DATASHEET!AA6) | AR5: =IF(DATASHEET!AB6=0,"",DATASHEET!AB6) | AS5: =IF(DATASHEET!AC6=0,"",DATASHEET!AC6) | AT5: =IF(DATASHEET!AD6=0,"",DATASHEET!AD6) | AU5: =IF(DATASHEET!AE6=0,"",DATASHEET!AE6)
A6: =IF(DATASHEET!A7=0,"",DATASHEET!A7) -> HUMANN RESOURCES 2010 | B6: =IF(DATASHEET!B7=0,"",DATASHEET!B7) -> A | C6: =IF(DATASHEET!C7=0,"",DATASHEET!C7) -> SS CTRL | D6: =IF(C6="CO-PLANTING",CONCATENATE(C6," ",F6),C6) -> SS CTRL | E6: =IF(DATASHEET!D7=0,"",DATASHEET!D7) -> 4 | F6: =IF(DATASHEET!E7=0,"",DATASHEET!E7) -> SS | G6: =IF(DATASHEET!F7=0,"",DATASHEET!F7) -> 42101 | H6: =IF(DATASHEET!G7=0,"",DATASHEET!G7) -> 46.736 | I6: =IF(DATASHEET!H7=0,"",DATASHEET!H7) -> 4.826 | J6: =IF(DATASHEET!I7=0,"",DATASHEET!I7) -> 42117 | K6: =IF(DATASHEET!J7=0,"",DATASHEET!J7) | L6: =IF(DATASHEET!K7=0,"",DATASHEET!K7) | M6: =IF(DATASHEET!L7=0,"",DATASHEET!L7) | N6: =J6-G6 -> 16 | O6: =IF(M6="",$H6,M6) -> 46.736 | P6: =IF(ISERROR($H6-M6),0,ABS($H6-M6)) -> 0 | Q6: 1 | R6: =IF(K6="Y",1,0) -> 0 | S6: =IF(L6="Y",1,0) -> 0 | T6: =IF(DATASHEET!M7=0,"",DATASHEET!M7) -> 42157 | U6: =IF(DATASHEET!N7=0,"",DATASHEET!N7) | V6: =IF(DATASHEET!O7=0,"",DATASHEET!O7) | W6: =IF(DATASHEET!Q7=0,"",DATASHEET!Q7) -> 55.88 | X6: =T6-$G6 -> 56 | Y6: =W6 -> 55.88 | Z6: =IF(AND($H6-W6>0,U6="Y"),ABS($H6-W6),0) -> 0 | AA6: 1 | AB6: =IF(U6="Y",1,0) -> 0 | AC6: =IF(V6="Y",1,0) -> 0 | AD6: =IF(DATASHEET!R7=0,"",DATASHEET!R7) -> 42233 | AE6: =IF(DATASHEET!S7=0,"",DATASHEET!S7) | AF6: =IF(DATASHEET!T7=0,"",DATASHEET!T7) | AG6: =IF(DATASHEET!V7=0,"",DATASHEET!V7) -> 66.8 | AH6: =AD6-$G6 -> 132 | AI6: =AG6 -> 66.8 | AJ6: =IF(AND($W6-AG6>0,AE6="Y"),ABS($W6-AG6),0) -> 0 | AK6: 1 | AL6: =IF(AE6="Y",1,0) -> 0 | AM6: =IF(AF6="Y",1,0) -> 0 | AN6: =IF(DATASHEET!X7=0,"",DATASHEET!X7) | AO6: =IF(DATASHEET!Y7=0,"",DATASHEET!Y7) | AP6: =IF(DATASHEET!Z7=0,"",DATASHEET!Z7) | AQ6: =IF(DATASHEET!AA7=0,"",DATASHEET!AA7) | AR6: =IF(DATASHEET!AB7=0,"",DATASHEET!AB7) | AS6: =IF(DATASHEET!AC7=0,"",DATASHEET!AC7) | AT6: =IF(DATASHEET!AD7=0,"",DATASHEET!AD7) | AU6: =IF(DATASHEET!AE7=0,"",DATASHEET!AE7)
A7: =IF(DATASHEET!A8=0,"",DATASHEET!A8) -> HUMANN RESOURCES 2010 | B7: =IF(DATASHEET!B8=0,"",DATASHEET!B8) -> A | C7: =IF(DATASHEET!C8=0,"",DATASHEET!C8) -> SS CTRL | D7: =IF(C7="CO-PLANTING",CONCATENATE(C7," ",F7),C7) -> SS CTRL | E7: =IF(DATASHEET!D8=0,"",DATASHEET!D8) -> 5 | F7: =IF(DATASHEET!E8=0,"",DATASHEET!E8) -> SS | G7: =IF(DATASHEET!F8=0,"",DATASHEET!F8) -> 42101 | H7: =IF(DATASHEET!G8=0,"",DATASHEET!G8) -> 49.022 | I7: =IF(DATASHEET!H8=0,"",DATASHEET!H8) -> 4.826 | J7: =IF(DATASHEET!I8=0,"",DATASHEET!I8) -> 42117 | K7: =IF(DATASHEET!J8=0,"",DATASHEET!J8) | L7: =IF(DATASHEET!K8=0,"",DATASHEET!K8) | M7: =IF(DATASHEET!L8=0,"",DATASHEET!L8) | N7: =J7-G7 -> 16 | O7: =IF(M7="",$H7,M7) -> 49.022 | P7: =IF(ISERROR($H7-M7),0,ABS($H7-M7)) -> 0 | Q7: 1 | R7: =IF(K7="Y",1,0) -> 0 | S7: =IF(L7="Y",1,0) -> 0 | T7: =IF(DATASHEET!M8=0,"",DATASHEET!M8) -> 42157 | U7: =IF(DATASHEET!N8=0,"",DATASHEET!N8) | V7: =IF(DATASHEET!O8=0,"",DATASHEET!O8) | W7: =IF(DATASHEET!Q8=0,"",DATASHEET!Q8) -> 49.784 | X7: =T7-$G7 -> 56 | Y7: =W7 -> 49.784 | Z7: =IF(AND($H7-W7>0,U7="Y"),ABS($H7-W7),0) -> 0 | AA7: 1 | AB7: =IF(U7="Y",1,0) -> 0 | AC7: =IF(V7="Y",1,0) -> 0 | AD7: =IF(DATASHEET!R8=0,"",DATASHEET!R8) -> 42233 | AE7: =IF(DATASHEET!S8=0,"",DATASHEET!S8) | AF7: =IF(DATASHEET!T8=0,"",DATASHEET!T8) -> Y | AG7: =IF(DATASHEET!V8=0,"",DATASHEET!V8) -> 53 | AH7: =AD7-$G7 -> 132 | AI7: =AG7 -> 53 | AJ7: =IF(AND($W7-AG7>0,AE7="Y"),ABS($W7-AG7),0) -> 0 | AK7: 1 | AL7: =IF(AE7="Y",1,0) -> 0 | AM7: =IF(AF7="Y",1,0) -> 1 | AN7: =IF(DATASHEET!X8=0,"",DATASHEET!X8) | AO7: =IF(DATASHEET!Y8=0,"",DATASHEET!Y8) | AP7: =IF(DATASHEET!Z8=0,"",DATASHEET!Z8) | AQ7: =IF(DATASHEET!AA8=0,"",DATASHEET!AA8) | AR7: =IF(DATASHEET!AB8=0,"",DATASHEET!AB8) | AS7: =IF(DATASHEET!AC8=0,"",DATASHEET!AC8) | AT7: =IF(DATASHEET!AD8=0,"",DATASHEET!AD8) | AU7: =IF(DATASHEET!AE8=0,"",DATASHEET!AE8)
A8: =IF(DATASHEET!A9=0,"",DATASHEET!A9) -> HUMANN RESOURCES 2010 | B8: =IF(DATASHEET!B9=0,"",DATASHEET!B9) -> A | C8: =IF(DATASHEET!C9=0,"",DATASHEET!C9) -> SS CTRL | D8: =IF(C8="CO-PLANTING",CONCATENATE(C8," ",F8),C8) -> SS CTRL | E8: =IF(DATASHEET!D9=0,"",DATASHEET!D9) -> 6 | F8: =IF(DATASHEET!E9=0,"",DATASHEET!E9) -> SS | G8: =IF(DATASHEET!F9=0,"",DATASHEET!F9) -> 42101 | H8: =IF(DATASHEET!G9=0,"",DATASHEET!G9) -> 33.02 | I8: =IF(DATASHEET!H9=0,"",DATASHEET!H9) -> 4.572 | J8: =IF(DATASHEET!I9=0,"",DATASHEET!I9) -> 42117 | K8: =IF(DATASHEET!J9=0,"",DATASHEET!J9) | L8: =IF(DATASHEET!K9=0,"",DATASHEET!K9) | M8: =IF(DATASHEET!L9=0,"",DATASHEET!L9) | N8: =J8-G8 -> 16 | O8: =IF(M8="",$H8,M8) -> 33.02 | P8: =IF(ISERROR($H8-M8),0,ABS($H8-M8)) -> 0 | Q8: 1 | R8: =IF(K8="Y",1,0) -> 0 | S8: =IF(L8="Y",1,0) -> 0 | T8: =IF(DATASHEET!M9=0,"",DATASHEET!M9) -> 42157 | U8: =IF(DATASHEET!N9=0,"",DATASHEET!N9) | V8: =IF(DATASHEET!O9=0,"",DATASHEET!O9) | W8: =IF(DATASHEET!Q9=0,"",DATASHEET!Q9) -> 38.354 | X8: =T8-$G8 -> 56 | Y8: =W8 -> 38.354 | Z8: =IF(AND($H8-W8>0,U8="Y"),ABS($H8-W8),0) -> 0 | AA8: 1 | AB8: =IF(U8="Y",1,0) -> 0 | AC8: =IF(V8="Y",1,0) -> 0 | AD8: =IF(DATASHEET!R9=0,"",DATASHEET!R9) -> 42233 | AE8: =IF(DATASHEET!S9=0,"",DATASHEET!S9) | AF8: =IF(DATASHEET!T9=0,"",DATASHEET!T9) -> Y | AG8: =IF(DATASHEET!V9=0,"",DATASHEET!V9) -> 43 | AH8: =AD8-$G8 -> 132 | AI8: =AG8 -> 43 | AJ8: =IF(AND($W8-AG8>0,AE8="Y"),ABS($W8-AG8),0) -> 0 | AK8: 1 | AL8: =IF(AE8="Y",1,0) -> 0 | AM8: =IF(AF8="Y",1,0) -> 1 | AN8: =IF(DATASHEET!X9=0,"",DATASHEET!X9) | AO8: =IF(DATASHEET!Y9=0,"",DATASHEET!Y9) | AP8: =IF(DATASHEET!Z9=0,"",DATASHEET!Z9) | AQ8: =IF(DATASHEET!AA9=0,"",DATASHEET!AA9) | AR8: =IF(DATASHEET!AB9=0,"",DATASHEET!AB9) | AS8: =IF(DATASHEET!AC9=0,"",DATASHEET!AC9) | AT8: =IF(DATASHEET!AD9=0,"",DATASHEET!AD9) | AU8: =IF(DATASHEET!AE9=0,"",DATASHEET!AE9)
A9: =IF(DATASHEET!A10=0,"",DATASHEET!A10) -> HUMANN RESOURCES 2010 | B9: =IF(DATASHEET!B10=0,"",DATASHEET!B10) -> A | C9: =IF(DATASHEET!C10=0,"",DATASHEET!C10) -> SS CTRL | D9: =IF(C9="CO-PLANTING",CONCATENATE(C9," ",F9),C9) -> SS CTRL | E9: =IF(DATASHEET!D10=0,"",DATASHEET!D10) -> 7 | F9: =IF(DATASHEET!E10=0,"",DATASHEET!E10) -> SS | G9: =IF(DATASHEET!F10=0,"",DATASHEET!F10) -> 42101 | H9: =IF(DATASHEET!G10=0,"",DATASHEET!G10) -> 45.72 | I9: =IF(DATASHEET!H10=0,"",DATASHEET!H10) -> 3.81 | J9: =IF(DATASHEET!I10=0,"",DATASHEET!I10) -> 42117 | K9: =IF(DATASHEET!J10=0,"",DATASHEET!J10) | L9: =IF(DATASHEET!K10=0,"",DATASHEET!K10) | M9: =IF(DATASHEET!L10=0,"",DATASHEET!L10) | N9: =J9-G9 -> 16 | O9: =IF(M9="",$H9,M9) -> 45.72 | P9: =IF(ISERROR($H9-M9),0,ABS($H9-M9)) -> 0 | Q9: 1 | R9: =IF(K9="Y",1,0) -> 0 | S9: =IF(L9="Y",1,0) -> 0 | T9: =IF(DATASHEET!M10=0,"",DATASHEET!M10) -> 42157 | U9: =IF(DATASHEET!N10=0,"",DATASHEET!N10) | V9: =IF(DATASHEET!O10=0,"",DATASHEET!O10) | W9: =IF(DATASHEET!Q10=0,"",DATASHEET!Q10) -> 54.61 | X9: =T9-$G9 -> 56 | Y9: =W9 -> 54.61 | Z9: =IF(AND($H9-W9>0,U9="Y"),ABS($H9-W9),0) -> 0 | AA9: 1 | AB9: =IF(U9="Y",1,0) -> 0 | AC9: =IF(V9="Y",1,0) -> 0 | AD9: =IF(DATASHEET!R10=0,"",DATASHEET!R10) -> 42233 | AE9: =IF(DATASHEET!S10=0,"",DATASHEET!S10) | AF9: =IF(DATASHEET!T10=0,"",DATASHEET!T10) -> Y | AG9: =IF(DATASHEET!V10=0,"",DATASHEET!V10) -> 60.5 | AH9: =AD9-$G9 -> 132 | AI9: =AG9 -> 60.5 | AJ9: =IF(AND($W9-AG9>0,AE9="Y"),ABS($W9-AG9),0) -> 0 | AK9: 1 | AL9: =IF(AE9="Y",1,0) -> 0 | AM9: =IF(AF9="Y",1,0) -> 1 | AN9: =IF(DATASHEET!X10=0,"",DATASHEET!X10) | AO9: =IF(DATASHEET!Y10=0,"",DATASHEET!Y10) | AP9: =IF(DATASHEET!Z10=0,"",DATASHEET!Z10) | AQ9: =IF(DATASHEET!AA10=0,"",DATASHEET!AA10) | AR9: =IF(DATASHEET!AB10=0,"",DATASHEET!AB10) | AS9: =IF(DATASHEET!AC10=0,"",DATASHEET!AC10) | AT9: =IF(DATASHEET!AD10=0,"",DATASHEET!AD10) | AU9: =IF(DATASHEET!AE10=0,"",DATASHEET!AE10)
A10: =IF(DATASHEET!A11=0,"",DATASHEET!A11) -> HUMANN RESOURCES 2010 | B10: =IF(DATASHEET!B11=0,"",DATASHEET!B11) -> A | C10: =IF(DATASHEET!C11=0,"",DATASHEET!C11) -> SS CTRL | D10: =IF(C10="CO-PLANTING",CONCATENATE(C10," ",F10),C10) -> SS CTRL | E10: =IF(DATASHEET!D11=0,"",DATASHEET!D11) -> 8 | F10: =IF(DATASHEET!E11=0,"",DATASHEET!E11) -> SS | G10: =IF(DATASHEET!F11=0,"",DATASHEET!F11) -> 42101 | H10: =IF(DATASHEET!G11=0,"",DATASHEET!G11) -> 39.878 | I10: =IF(DATASHEET!H11=0,"",DATASHEET!H11) -> 3.81 | J10: =IF(DATASHEET!I11=0,"",DATASHEET!I11) -> 42117 | K10: =IF(DATASHEET!J11=0,"",DATASHEET!J11) | L10: =IF(DATASHEET!K11=0,"",DATASHEET!K11) | M10: =IF(DATASHEET!L11=0,"",DATASHEET!L11) | N10: =J10-G10 -> 16 | O10: =IF(M10="",$H10,M10) -> 39.878 | P10: =IF(ISERROR($H10-M10),0,ABS($H10-M10)) -> 0 | Q10: 1 | R10: =IF(K10="Y",1,0) -> 0 | S10: =IF(L10="Y",1,0) -> 0 | T10: =IF(DATASHEET!M11=0,"",DATASHEET!M11) -> 42157 | U10: =IF(DATASHEET!N11=0,"",DATASHEET!N11) | V10: =IF(DATASHEET!O11=0,"",DATASHEET!O11) | W10: =IF(DATASHEET!Q11=0,"",DATASHEET!Q11) -> 43.18 | X10: =T10-$G10 -> 56 | Y10: =W10 -> 43.18 | Z10: =IF(AND($H10-W10>0,U10="Y"),ABS($H10-W10),0) -> 0 | AA10: 1 | AB10: =IF(U10="Y",1,0) -> 0 | AC10: =IF(V10="Y",1,0) -> 0 | AD10: =IF(DATASHEET!R11=0,"",DATASHEET!R11) -> 42233 | AE10: =IF(DATASHEET!S11=0,"",DATASHEET!S11) | AF10: =IF(DATASHEET!T11=0,"",DATASHEET!T11) -> Y | AG10: =IF(DATASHEET!V11=0,"",DATASHEET!V11) -> 48 | AH10: =AD10-$G10 -> 132 | AI10: =AG10 -> 48 | AJ10: =IF(AND($W10-AG10>0,AE10="Y"),ABS($W10-AG10),0) -> 0 | AK10: 1 | AL10: =IF(AE10="Y",1,0) -> 0 | AM10: =IF(AF10="Y",1,0) -> 1 | AN10: =IF(DATASHEET!X11=0,"",DATASHEET!X11) | AO10: =IF(DATASHEET!Y11=0,"",DATASHEET!Y11) | AP10: =IF(DATASHEET!Z11=0,"",DATASHEET!Z11) | AQ10: =IF(DATASHEET!AA11=0,"",DATASHEET!AA11) | AR10: =IF(DATASHEET!AB11=0,"",DATASHEET!AB11) | AS10: =IF(DATASHEET!AC11=0,"",DATASHEET!AC11) | AT10: =IF(DATASHEET!AD11=0,"",DATASHEET!AD11) | AU10: =IF(DATASHEET!AE11=0,"",DATASHEET!AE11)
A11: =IF(DATASHEET!A12=0,"",DATASHEET!A12) -> HUMANN RESOURCES 2010 | B11: =IF(DATASHEET!B12=0,"",DATASHEET!B12) -> A | C11: =IF(DATASHEET!C12=0,"",DATASHEET!C12) -> SS CTRL | D11: =IF(C11="CO-PLANTING",CONCATENATE(C11," ",F11),C11) -> SS CTRL | E11: =IF(DATASHEET!D12=0,"",DATASHEET!D12) -> 9 | F11: =IF(DATASHEET!E12=0,"",DATASHEET!E12) -> SS | G11: =IF(DATASHEET!F12=0,"",DATASHEET!F12) -> 42101 | H11: =IF(DATASHEET!G12=0,"",DATASHEET!G12) -> 40.894 | I11: =IF(DATASHEET!H12=0,"",DATASHEET!H12) -> 4.318 | J11: =IF(DATASHEET!I12=0,"",DATASHEET!I12) -> 42117 | K11: =IF(DATASHEET!J12=0,"",DATASHEET!J12) | L11: =IF(DATASHEET!K12=0,"",DATASHEET!K12) | M11: =IF(DATASHEET!L12=0,"",DATASHEET!L12) | N11: =J11-G11 -> 16 | O11: =IF(M11="",$H11,M11) -> 40.894 | P11: =IF(ISERROR($H11-M11),0,ABS($H11-M11)) -> 0 | Q11: 1 | R11: =IF(K11="Y",1,0) -> 0 | S11: =IF(L11="Y",1,0) -> 0 | T11: =IF(DATASHEET!M12=0,"",DATASHEET!M12) -> 42157 | U11: =IF(DATASHEET!N12=0,"",DATASHEET!N12) | V11: =IF(DATASHEET!O12=0,"",DATASHEET!O12) | W11: =IF(DATASHEET!Q12=0,"",DATASHEET!Q12) -> 51.308 | X11: =T11-$G11 -> 56 | Y11: =W11 -> 51.308 | Z11: =IF(AND($H11-W11>0,U11="Y"),ABS($H11-W11),0) -> 0 | AA11: 1 | AB11: =IF(U11="Y",1,0) -> 0 | AC11: =IF(V11="Y",1,0) -> 0 | AD11: =IF(DATASHEET!R12=0,"",DATASHEET!R12) -> 42233 | AE11: =IF(DATASHEET!S12=0,"",DATASHEET!S12) | AF11: =IF(DATASHEET!T12=0,"",DATASHEET!T12) -> Y | AG11: =IF(DATASHEET!V12=0,"",DATASHEET!V12) -> 58 | AH11: =AD11-$G11 -> 132 | AI11: =AG11 -> 58 | AJ11: =IF(AND($W11-AG11>0,AE11="Y"),ABS($W11-AG11),0) -> 0 | AK11: 1 | AL11: =IF(AE11="Y",1,0) -> 0 | AM11: =IF(AF11="Y",1,0) -> 1 | AN11: =IF(DATASHEET!X12=0,"",DATASHEET!X12) | AO11: =IF(DATASHEET!Y12=0,"",DATASHEET!Y12) | AP11: =IF(DATASHEET!Z12=0,"",DATASHEET!Z12) | AQ11: =IF(DATASHEET!AA12=0,"",DATASHEET!AA12) | AR11: =IF(DATASHEET!AB12=0,"",DATASHEET!AB12) | AS11: =IF(DATASHEET!AC12=0,"",DATASHEET!AC12) | AT11: =IF(DATASHEET!AD12=0,"",DATASHEET!AD12) | AU11: =IF(DATASHEET!AE12=0,"",DATASHEET!AE12)
A12: =IF(DATASHEET!A13=0,"",DATASHEET!A13) -> HUMANN RESOURCES 2010 | B12: =IF(DATASHEET!B13=0,"",DATASHEET!B13) -> A | C12: =IF(DATASHEET!C13=0,"",DATASHEET!C13) -> SS CTRL | D12: =IF(C12="CO-PLANTING",CONCATENATE(C12," ",F12),C12) -> SS CTRL | E12: =IF(DATASHEET!D13=0,"",DATASHEET!D13) -> 10 | F12: =IF(DATASHEET!E13=0,"",DATASHEET!E13) -> SS | G12: =IF(DATASHEET!F13=0,"",DATASHEET!F13) -> 42101 | H12: =IF(DATASHEET!G13=0,"",DATASHEET!G13) -> 40.894 | I12: =IF(DATASHEET!H13=0,"",DATASHEET!H13) -> 4.572 | J12: =IF(DATASHEET!I13=0,"",DATASHEET!I13) -> 42117 | K12: =IF(DATASHEET!J13=0,"",DATASHEET!J13) | L12: =IF(DATASHEET!K13=0,"",DATASHEET!K13) | M12: =IF(DATASHEET!L13=0,"",DATASHEET!L13) | N12: =J12-G12 -> 16 | O12: =IF(M12="",$H12,M12) -> 40.894 | P12: =IF(ISERROR($H12-M12),0,ABS($H12-M12)) -> 0 | Q12: 1 | R12: =IF(K12="Y",1,0) -> 0 | S12: =IF(L12="Y",1,0) -> 0 | T12: =IF(DATASHEET!M13=0,"",DATASHEET!M13) -> 42157 | U12: =IF(DATASHEET!N13=0,"",DATASHEET!N13) | V12: =IF(DATASHEET!O13=0,"",DATASHEET!O13) | W12: =IF(DATASHEET!Q13=0,"",DATASHEET!Q13) -> 48.006 | X12: =T12-$G12 -> 56 | Y12: =W12 -> 48.006 | Z12: =IF(AND($H12-W12>0,U12="Y"),ABS($H12-W12),0) -> 0 | AA12: 1 | AB12: =IF(U12="Y",1,0) -> 0 | AC12: =IF(V12="Y",1,0) -> 0 | AD12: =IF(DATASHEET!R13=0,"",DATASHEET!R13) -> 42233 | AE12: =IF(DATASHEET!S13=0,"",DATASHEET!S13) | AF12: =IF(DATASHEET!T13=0,"",DATASHEET!T13) -> Y | AG12: =IF(DATASHEET!V13=0,"",DATASHEET!V13) -> 54 | AH12: =AD12-$G12 -> 132 | AI12: =AG12 -> 54 | AJ12: =IF(AND($W12-AG12>0,AE12="Y"),ABS($W12-AG12),0) -> 0 | AK12: 1 | AL12: =IF(AE12="Y",1,0) -> 0 | AM12: =IF(AF12="Y",1,0) -> 1 | AN12: =IF(DATASHEET!X13=0,"",DATASHEET!X13) | AO12: =IF(DATASHEET!Y13=0,"",DATASHEET!Y13) | AP12: =IF(DATASHEET!Z13=0,"",DATASHEET!Z13) | AQ12: =IF(DATASHEET!AA13=0,"",DATASHEET!AA13) | AR12: =IF(DATASHEET!AB13=0,"",DATASHEET!AB13) | AS12: =IF(DATASHEET!AC13=0,"",DATASHEET!AC13) | AT12: =IF(DATASHEET!AD13=0,"",DATASHEET!AD13) | AU12: =IF(DATASHEET!AE13=0,"",DATASHEET!AE13)
A13: =IF(DATASHEET!A14=0,"",DATASHEET!A14) -> HUMANN RESOURCES 2010 | B13: =IF(DATASHEET!B14=0,"",DATASHEET!B14) -> A | C13: =IF(DATASHEET!C14=0,"",DATASHEET!C14) -> SS CTRL | D13: =IF(C13="CO-PLANTING",CONCATENATE(C13," ",F13),C13) -> SS CTRL | E13: =IF(DATASHEET!D14=0,"",DATASHEET!D14) -> 11 | F13: =IF(DATASHEET!E14=0,"",DATASHEET!E14) -> SS | G13: =IF(DATASHEET!F14=0,"",DATASHEET!F14) -> 42101 | H13: =IF(DATASHEET!G14=0,"",DATASHEET!G14) -> 38.608 | I13: =IF(DATASHEET!H14=0,"",DATASHEET!H14) -> 4.064 | J13: =IF(DATASHEET!I14=0,"",DATASHEET!I14) -> 42117 | K13: =IF(DATASHEET!J14=0,"",DATASHEET!J14) | L13: =IF(DATASHEET!K14=0,"",DATASHEET!K14) | M13: =IF(DATASHEET!L14=0,"",DATASHEET!L14) | N13: =J13-G13 -> 16 | O13: =IF(M13="",$H13,M13) -> 38.608 | P13: =IF(ISERROR($H13-M13),0,ABS($H13-M13)) -> 0 | Q13: 1 | R13: =IF(K13="Y",1,0) -> 0 | S13: =IF(L13="Y",1,0) -> 0 | T13: =IF(DATASHEET!M14=0,"",DATASHEET!M14) -> 42157 | U13: =IF(DATASHEET!N14=0,"",DATASHEET!N14) | V13: =IF(DATASHEET!O14=0,"",DATASHEET!O14) | W13: =IF(DATASHEET!Q14=0,"",DATASHEET!Q14) -> 52.832 | X13: =T13-$G13 -> 56 | Y13: =W13 -> 52.832 | Z13: =IF(AND($H13-W13>0,U13="Y"),ABS($H13-W13),0) -> 0 | AA13: 1 | AB13: =IF(U13="Y",1,0) -> 0 | AC13: =IF(V13="Y",1,0) -> 0 | AD13: =IF(DATASHEET!R14=0,"",DATASHEET!R14) -> 42233 | AE13: =IF(DATASHEET!S14=0,"",DATASHEET!S14) | AF13: =IF(DATASHEET!T14=0,"",DATASHEET!T14) | AG13: =IF(DATASHEET!V14=0,"",DATASHEET!V14) -> 63 | AH13: =AD13-$G13 -> 132 | AI13: =AG13 -> 63 | AJ13: =IF(AND($W13-AG13>0,AE13="Y"),ABS($W13-AG13),0) -> 0 | AK13: 1 | AL13: =IF(AE13="Y",1,0) -> 0 | AM13: =IF(AF13="Y",1,0) -> 0 | AN13: =IF(DATASHEET!X14=0,"",DATASHEET!X14) | AO13: =IF(DATASHEET!Y14=0,"",DATASHEET!Y14) | AP13: =IF(DATASHEET!Z14=0,"",DATASHEET!Z14) | AQ13: =IF(DATASHEET!AA14=0,"",DATASHEET!AA14) | AR13: =IF(DATASHEET!AB14=0,"",DATASHEET!AB14) | AS13: =IF(DATASHEET!AC14=0,"",DATASHEET!AC14) | AT13: =IF(DATASHEET!AD14=0,"",DATASHEET!AD14) | AU13: =IF(DATASHEET!AE14=0,"",DATASHEET!AE14)
A14: =IF(DATASHEET!A15=0,"",DATASHEET!A15) -> HUMANN RESOURCES 2010 | B14: =IF(DATASHEET!B15=0,"",DATASHEET!B15) -> A | C14: =IF(DATASHEET!C15=0,"",DATASHEET!C15) -> SS CTRL | D14: =IF(C14="CO-PLANTING",CONCATENATE(C14," ",F14),C14) -> SS CTRL | E14: =IF(DATASHEET!D15=0,"",DATASHEET!D15) -> 12 | F14: =IF(DATASHEET!E15=0,"",DATASHEET!E15) -> SS | G14: =IF(DATASHEET!F15=0,"",DATASHEET!F15) -> 42101 | H14: =IF(DATASHEET!G15=0,"",DATASHEET!G15) -> 38.862 | I14: =IF(DATASHEET!H15=0,"",DATASHEET!H15) -> 4.826 | J14: =IF(DATASHEET!I15=0,"",DATASHEET!I15) -> 42117 | K14: =IF(DATASHEET!J15=0,"",DATASHEET!J15) | L14: =IF(DATASHEET!K15=0,"",DATASHEET!K15) | M14: =IF(DATASHEET!L15=0,"",DATASHEET!L15) | N14: =J14-G14 -> 16 | O14: =IF(M14="",$H14,M14) -> 38.862 | P14: =IF(ISERROR($H14-M14),0,ABS($H14-M14)) -> 0 | Q14: 1 | R14: =IF(K14="Y",1,0) -> 0 | S14: =IF(L14="Y",1,0) -> 0 | T14: =IF(DATASHEET!M15=0,"",DATASHEET!M15) -> 42157 | U14: =IF(DATASHEET!N15=0,"",DATASHEET!N15) | V14: =IF(DATASHEET!O15=0,"",DATASHEET!O15) | W14: =IF(DATASHEET!Q15=0,"",DATASHEET!Q15) -> 46.228 | X14: =T14-$G14 -> 56 | Y14: =W14 -> 46.228 | Z14: =IF(AND($H14-W14>0,U14="Y"),ABS($H14-W14),0) -> 0 | AA14: 1 | AB14: =IF(U14="Y",1,0) -> 0 | AC14: =IF(V14="Y",1,0) -> 0 | AD14: =IF(DATASHEET!R15=0,"",DATASHEET!R15) -> 42233 | AE14: =IF(DATASHEET!S15=0,"",DATASHEET!S15) | AF14: =IF(DATASHEET!T15=0,"",DATASHEET!T15) -> Y | AG14: =IF(DATASHEET!V15=0,"",DATASHEET!V15) -> 55 | AH14: =AD14-$G14 -> 132 | AI14: =AG14 -> 55 | AJ14: =IF(AND($W14-AG14>0,AE14="Y"),ABS($W14-AG14),0) -> 0 | AK14: 1 | AL14: =IF(AE14="Y",1,0) -> 0 | AM14: =IF(AF14="Y",1,0) -> 1 | AN14: =IF(DATASHEET!X15=0,"",DATASHEET!X15) | AO14: =IF(DATASHEET!Y15=0,"",DATASHEET!Y15) | AP14: =IF(DATASHEET!Z15=0,"",DATASHEET!Z15) | AQ14: =IF(DATASHEET!AA15=0,"",DATASHEET!AA15) | AR14: =IF(DATASHEET!AB15=0,"",DATASHEET!AB15) | AS14: =IF(DATASHEET!AC15=0,"",DATASHEET!AC15) | AT14: =IF(DATASHEET!AD15=0,"",DATASHEET!AD15) | AU14: =IF(DATASHEET!AE15=0,"",DATASHEET!AE15)
A15: =IF(DATASHEET!A16=0,"",DATASHEET!A16) -> HUMANN RESOURCES 2010 | B15: =IF(DATASHEET!B16=0,"",DATASHEET!B16) -> A | C15: =IF(DATASHEET!C16=0,"",DATASHEET!C16) -> SS CTRL | D15: =IF(C15="CO-PLANTING",CONCATENATE(C15," ",F15),C15) -> SS CTRL | E15: =IF(DATASHEET!D16=0,"",DATASHEET!D16) -> 13 | F15: =IF(DATASHEET!E16=0,"",DATASHEET!E16) -> SS | G15: =IF(DATASHEET!F16=0,"",DATASHEET!F16) -> 42101 | H15: =IF(DATASHEET!G16=0,"",DATASHEET!G16) -> 36.576 | I15: =IF(DATASHEET!H16=0,"",DATASHEET!H16) -> 3.302 | J15: =IF(DATASHEET!I16=0,"",DATASHEET!I16) -> 42117 | K15: =IF(DATASHEET!J16=0,"",DATASHEET!J16) | L15: =IF(DATASHEET!K16=0,"",DATASHEET!K16) | M15: =IF(DATASHEET!L16=0,"",DATASHEET!L16) | N15: =J15-G15 -> 16 | O15: =IF(M15="",$H15,M15) -> 36.576 | P15: =IF(ISERROR($H15-M15),0,ABS($H15-M15)) -> 0 | Q15: 1 | R15: =IF(K15="Y",1,0) -> 0 | S15: =IF(L15="Y",1,0) -> 0 | T15: =IF(DATASHEET!M16=0,"",DATASHEET!M16) -> 42157 | U15: =IF(DATASHEET!N16=0,"",DATASHEET!N16) | V15: =IF(DATASHEET!O16=0,"",DATASHEET!O16) | W15: =IF(DATASHEET!Q16=0,"",DATASHEET!Q16) -> 46.736 | X15: =T15-$G15 -> 56 | Y15: =W15 -> 46.736 | Z15: =IF(AND($H15-W15>0,U15="Y"),ABS($H15-W15),0) -> 0 | AA15: 1 | AB15: =IF(U15="Y",1,0) -> 0 | AC15: =IF(V15="Y",1,0) -> 0 | AD15: =IF(DATASHEET!R16=0,"",DATASHEET!R16) -> 42233 | AE15: =IF(DATASHEET!S16=0,"",DATASHEET!S16) | AF15: =IF(DATASHEET!T16=0,"",DATASHEET!T16) -> Y | AG15: =IF(DATASHEET!V16=0,"",DATASHEET!V16) -> 56 | AH15: =AD15-$G15 -> 132 | AI15: =AG15 -> 56 | AJ15: =IF(AND($W15-AG15>0,AE15="Y"),ABS($W15-AG15),0) -> 0 | AK15: 1 | AL15: =IF(AE15="Y",1,0) -> 0 | AM15: =IF(AF15="Y",1,0) -> 1 | AN15: =IF(DATASHEET!X16=0,"",DATASHEET!X16) | AO15: =IF(DATASHEET!Y16=0,"",DATASHEET!Y16) | AP15: =IF(DATASHEET!Z16=0,"",DATASHEET!Z16) | AQ15: =IF(DATASHEET!AA16=0,"",DATASHEET!AA16) | AR15: =IF(DATASHEET!AB16=0,"",DATASHEET!AB16) | AS15: =IF(DATASHEET!AC16=0,"",DATASHEET!AC16) | AT15: =IF(DATASHEET!AD16=0,"",DATASHEET!AD16) | AU15: =IF(DATASHEET!AE16=0,"",DATASHEET!AE16)
A16: =IF(DATASHEET!A17=0,"",DATASHEET!A17) -> HUMANN RESOURCES 2010 | B16: =IF(DATASHEET!B17=0,"",DATASHEET!B17) -> A | C16: =IF(DATASHEET!C17=0,"",DATASHEET!C17) -> SS CTRL | D16: =IF(C16="CO-PLANTING",CONCATENATE(C16," ",F16),C16) -> SS CTRL | E16: =IF(DATASHEET!D17=0,"",DATASHEET!D17) -> 14 | F16: =IF(DATASHEET!E17=0,"",DATASHEET!E17) -> SS | G16: =IF(DATASHEET!F17=0,"",DATASHEET!F17) -> 42101 | H16: =IF(DATASHEET!G17=0,"",DATASHEET!G17) -> 39.116 | I16: =IF(DATASHEET!H17=0,"",DATASHEET!H17) -> 4.826 | J16: =IF(DATASHEET!I17=0,"",DATASHEET!I17) -> 42117 | K16: =IF(DATASHEET!J17=0,"",DATASHEET!J17) | L16: =IF(DATASHEET!K17=0,"",DATASHEET!K17) | M16: =IF(DATASHEET!L17=0,"",DATASHEET!L17) | N16: =J16-G16 -> 16 | O16: =IF(M16="",$H16,M16) -> 39.116 | P16: =IF(ISERROR($H16-M16),0,ABS($H16-M16)) -> 0 | Q16: 1 | R16: =IF(K16="Y",1,0) -> 0 | S16: =IF(L16="Y",1,0) -> 0 | T16: =IF(DATASHEET!M17=0,"",DATASHEET!M17) -> 42157 | U16: =IF(DATASHEET!N17=0,"",DATASHEET!N17) | V16: =IF(DATASHEET!O17=0,"",DATASHEET!O17) | W16: =IF(DATASHEET!Q17=0,"",DATASHEET!Q17) -> 52.07 | X16: =T16-$G16 -> 56 | Y16: =W16 -> 52.07 | Z16: =IF(AND($H16-W16>0,U16="Y"),ABS($H16-W16),0) -> 0 | AA16: 1 | AB16: =IF(U16="Y",1,0) -> 0 | AC16: =IF(V16="Y",1,0) -> 0 | AD16: =IF(DATASHEET!R17=0,"",DATASHEET!R17) -> 42233 | AE16: =IF(DATASHEET!S17=0,"",DATASHEET!S17) | AF16: =IF(DATASHEET!T17=0,"",DATASHEET!T17) -> Y | AG16: =IF(DATASHEET!V17=0,"",DATASHEET!V17) -> 59 | AH16: =AD16-$G16 -> 132 | AI16: =AG16 -> 59 | AJ16: =IF(AND($W16-AG16>0,AE16="Y"),ABS($W16-AG16),0) -> 0 | AK16: 1 | AL16: =IF(AE16="Y",1,0) -> 0 | AM16: =IF(AF16="Y",1,0) -> 1 | AN16: =IF(DATASHEET!X17=0,"",DATASHEET!X17) | AO16: =IF(DATASHEET!Y17=0,"",DATASHEET!Y17) | AP16: =IF(DATASHEET!Z17=0,"",DATASHEET!Z17) | AQ16: =IF(DATASHEET!AA17=0,"",DATASHEET!AA17) | AR16: =IF(DATASHEET!AB17=0,"",DATASHEET!AB17) | AS16: =IF(DATASHEET!AC17=0,"",DATASHEET!AC17) | AT16: =IF(DATASHEET!AD17=0,"",DATASHEET!AD17) | AU16: =IF(DATASHEET!AE17=0,"",DATASHEET!AE17)
... A31: =IF(DATASHEET!A32=0,"",DATASHEET!A32) -> HUMANN RESOURCES 2010 | B31: =IF(DATASHEET!B32=0,"",DATASHEET!B32) -> B | C31: =IF(DATASHEET!C32=0,"",DATASHEET!C32) -> PLANTSKYDD | D31: =IF(C31="CO-PLANTING",CONCATENATE(C31," ",F31),C31) -> PLANTSKYDD | E31: =IF(DATASHEET!D32=0,"",DATASHEET!D32) -> 9 | F31: =IF(DATASHEET!E32=0,"",DATASHEET!E32) -> WRC | G31: =IF(DATASHEET!F32=0,"",DATASHEET!F32) -> 42101 | H31: =IF(DATASHEET!G32=0,"",DATASHEET!G32) -> 48.26 | I31: =IF(DATASHEET!H32=0,"",DATASHEET!H32) -> 4.318 | J31: =IF(DATASHEET!I32=0,"",DATASHEET!I32) -> 42117 | K31: =IF(DATASHEET!J32=0,"",DATASHEET!J32) | L31: =IF(DATASHEET!K32=0,"",DATASHEET!K32) | M31: =IF(DATASHEET!L32=0,"",DATASHEET!L32) | N31: =J31-G31 -> 16 | O31: =IF(M31="",$H31,M31) -> 48.26 | P31: =IF(ISERROR($H31-M31),0,ABS($H31-M31)) -> 0 | Q31: 1 | R31: =IF(K31="Y",1,0) -> 0 | S31: =IF(L31="Y",1,0) -> 0 | T31: =IF(DATASHEET!M32=0,"",DATASHEET!M32) -> 42157 | U31: =IF(DATASHEET!N32=0,"",DATASHEET!N32) | V31: =IF(DATASHEET!O32=0,"",DATASHEET!O32) | W31: =IF(DATASHEET!Q32=0,"",DATASHEET!Q32) -> 51.054 | X31: =T31-$G31 -> 56 | Y31: =W31 -> 51.054 | Z31: =IF(AND($H31-W31>0,U31="Y"),ABS($H31-W31),0) -> 0 | AA31: 1 | AB31: =IF(U31="Y",1,0) -> 0 | AC31: =IF(V31="Y",1,0) -> 0 | AD31: =IF(DATASHEET!R32=0,"",DATASHEET!R32) -> 42233 | AE31: =IF(DATASHEET!S32=0,"",DATASHEET!S32) | AF31: =IF(DATASHEET!T32=0,"",DATASHEET!T32) -> Y | AG31: =IF(DATASHEET!V32=0,"",DATASHEET!V32) -> 54 | AH31: =AD31-$G31 -> 132 | AI31: =AG31 -> 54 | AJ31: =IF(AND($W31-AG31>0,AE31="Y"),ABS($W31-AG31),0) -> 0 | AK31: 1 | AL31: =IF(AE31="Y",1,0) -> 0 | AM31: =IF(AF31="Y",1,0) -> 1 | AN31: =IF(DATASHEET!X32=0,"",DATASHEET!X32) | AO31: =IF(DATASHEET!Y32=0,"",DATASHEET!Y32) | AP31: =IF(DATASHEET!Z32=0,"",DATASHEET!Z32) | AQ31: =IF(DATASHEET!AA32=0,"",DATASHEET!AA32) | AR31: =IF(DATASHEET!AB32=0,"",DATASHEET!AB32) | AS31: =IF(DATASHEET!AC32=0,"",DATASHEET!AC32) | AT31: =IF(DATASHEET!AD32=0,"",DATASHEET!AD32) | AU31: =IF(DATASHEET!AE32=0,"",DATASHEET!AE32)
A32: =IF(DATASHEET!A33=0,"",DATASHEET!A33) -> HUMANN RESOURCES 2010 | B32: =IF(DATASHEET!B33=0,"",DATASHEET!B33) -> B | C32: =IF(DATASHEET!C33=0,"",DATASHEET!C33) -> PLANTSKYDD | D32: =IF(C32="CO-PLANTING",CONCATENATE(C32," ",F32),C32) -> PLANTSKYDD | E32: =IF(DATASHEET!D33=0,"",DATASHEET!D33) -> 10 | F32: =IF(DATASHEET!E33=0,"",DATASHEET!E33) -> WRC | G32: =IF(DATASHEET!F33=0,"",DATASHEET!F33) -> 42101 | H32: =IF(DATASHEET!G33=0,"",DATASHEET!G33) -> 27.94 | I32: =IF(DATASHEET!H33=0,"",DATASHEET!H33) -> 2.032 | J32: =IF(DATASHEET!I33=0,"",DATASHEET!I33) -> 42117 | K32: =IF(DATASHEET!J33=0,"",DATASHEET!J33) | L32: =IF(DATASHEET!K33=0,"",DATASHEET!K33) | M32: =IF(DATASHEET!L33=0,"",DATASHEET!L33) | N32: =J32-G32 -> 16 | O32: =IF(M32="",$H32,M32) -> 27.94 | P32: =IF(ISERROR($H32-M32),0,ABS($H32-M32)) -> 0 | Q32: 1 | R32: =IF(K32="Y",1,0) -> 0 | S32: =IF(L32="Y",1,0) -> 0 | T32: =IF(DATASHEET!M33=0,"",DATASHEET!M33) -> 42157 | U32: =IF(DATASHEET!N33=0,"",DATASHEET!N33) | V32: =IF(DATASHEET!O33=0,"",DATASHEET!O33) | W32: =IF(DATASHEET!Q33=0,"",DATASHEET!Q33) -> 33.02 | X32: =T32-$G32 -> 56 | Y32: =W32 -> 33.02 | Z32: =IF(AND($H32-W32>0,U32="Y"),ABS($H32-W32),0) -> 0 | AA32: 1 | AB32: =IF(U32="Y",1,0) -> 0 | AC32: =IF(V32="Y",1,0) -> 0 | AD32: =IF(DATASHEET!R33=0,"",DATASHEET!R33) -> 42233 | AE32: =IF(DATASHEET!S33=0,"",DATASHEET!S33) | AF32: =IF(DATASHEET!T33=0,"",DATASHEET!T33) -> Y | AG32: =IF(DATASHEET!V33=0,"",DATASHEET!V33) | AH32: =AD32-$G32 -> 132 | AI32: =AG32 | AK32: 1 | AL32: =IF(AE32="Y",1,0) -> 0 | AM32: =IF(AF32="Y",1,0) -> 1 | AN32: =IF(DATASHEET!X33=0,"",DATASHEET!X33) | AO32: =IF(DATASHEET!Y33=0,"",DATASHEET!Y33) | AP32: =IF(DATASHEET!Z33=0,"",DATASHEET!Z33) | AQ32: =IF(DATASHEET!AA33=0,"",DATASHEET!AA33) | AR32: =IF(DATASHEET!AB33=0,"",DATASHEET!AB33) | AS32: =IF(DATASHEET!AC33=0,"",DATASHEET!AC33) | AT32: =IF(DATASHEET!AD33=0,"",DATASHEET!AD33) | AU32: =IF(DATASHEET!AE33=0,"",DATASHEET!AE33)
A33: =IF(DATASHEET!A34=0,"",DATASHEET!A34) -> HUMANN RESOURCES 2010 | B33: =IF(DATASHEET!B34=0,"",DATASHEET!B34) -> B | C33: =IF(DATASHEET!C34=0,"",DATASHEET!C34) -> PLANTSKYDD | D33: =IF(C33="CO-PLANTING",CONCATENATE(C33," ",F33),C33) -> PLANTSKYDD | E33: =IF(DATASHEET!D34=0,"",DATASHEET!D34) -> 11 | F33: =IF(DATASHEET!E34=0,"",DATASHEET!E34) -> WRC | G33: =IF(DATASHEET!F34=0,"",DATASHEET!F34) -> 42101 | H33: =IF(DATASHEET!G34=0,"",DATASHEET!G34) -> 27.94 | I33: =IF(DATASHEET!H34=0,"",DATASHEET!H34) -> 4.572 | J33: =IF(DATASHEET!I34=0,"",DATASHEET!I34) -> 42117 | K33: =IF(DATASHEET!J34=0,"",DATASHEET!J34) | L33: =IF(DATASHEET!K34=0,"",DATASHEET!K34) | M33: =IF(DATASHEET!L34=0,"",DATASHEET!L34) | N33: =J33-G33 -> 16 | O33: =IF(M33="",$H33,M33) -> 27.94 | P33: =IF(ISERROR($H33-M33),0,ABS($H33-M33)) -> 0 | Q33: 1 | R33: =IF(K33="Y",1,0) -> 0 | S33: =IF(L33="Y",1,0) -> 0 | T33: =IF(DATASHEET!M34=0,"",DATASHEET!M34) -> 42157 | U33: =IF(DATASHEET!N34=0,"",DATASHEET!N34) | V33: =IF(DATASHEET!O34=0,"",DATASHEET!O34) | W33: =IF(DATASHEET!Q34=0,"",DATASHEET!Q34) -> 38.608 | X33: =T33-$G33 -> 56 | Y33: =W33 -> 38.608 | Z33: =IF(AND($H33-W33>0,U33="Y"),ABS($H33-W33),0) -> 0 | AA33: 1 | AB33: =IF(U33="Y",1,0) -> 0 | AC33: =IF(V33="Y",1,0) -> 0 | AD33: =IF(DATASHEET!R34=0,"",DATASHEET!R34) -> 42233 | AE33: =IF(DATASHEET!S34=0,"",DATASHEET!S34) | AF33: =IF(DATASHEET!T34=0,"",DATASHEET!T34) -> Y | AG33: =IF(DATASHEET!V34=0,"",DATASHEET!V34) -> 42 | AH33: =AD33-$G33 -> 132 | AI33: =AG33 -> 42 | AJ33: =IF(AND($W33-AG33>0,AE33="Y"),ABS($W33-AG33),0) -> 0 | AK33: 1 | AL33: =IF(AE33="Y",1,0) -> 0 | AM33: =IF(AF33="Y",1,0) -> 1 | AN33: =IF(DATASHEET!X34=0,"",DATASHEET!X34) | AO33: =IF(DATASHEET!Y34=0,"",DATASHEET!Y34) | AP33: =IF(DATASHEET!Z34=0,"",DATASHEET!Z34) | AQ33: =IF(DATASHEET!AA34=0,"",DATASHEET!AA34) | AR33: =IF(DATASHEET!AB34=0,"",DATASHEET!AB34) | AS33: =IF(DATASHEET!AC34=0,"",DATASHEET!AC34) | AT33: =IF(DATASHEET!AD34=0,"",DATASHEET!AD34) | AU33: =IF(DATASHEET!AE34=0,"",DATASHEET!AE34)
A34: =IF(DATASHEET!A35=0,"",DATASHEET!A35) -> HUMANN RESOURCES 2010 | B34: =IF(DATASHEET!B35=0,"",DATASHEET!B35) -> B | C34: =IF(DATASHEET!C35=0,"",DATASHEET!C35) -> PLANTSKYDD | D34: =IF(C34="CO-PLANTING",CONCATENATE(C34," ",F34),C34) -> PLANTSKYDD | E34: =IF(DATASHEET!D35=0,"",DATASHEET!D35) -> 12 | F34: =IF(DATASHEET!E35=0,"",DATASHEET!E35) -> WRC | G34: =IF(DATASHEET!F35=0,"",DATASHEET!F35) -> 42101 | H34: =IF(DATASHEET!G35=0,"",DATASHEET!G35) -> 27.94 | I34: =IF(DATASHEET!H35=0,"",DATASHEET!H35) -> 3.302 | J34: =IF(DATASHEET!I35=0,"",DATASHEET!I35) -> 42117 | K34: =IF(DATASHEET!J35=0,"",DATASHEET!J35) | L34: =IF(DATASHEET!K35=0,"",DATASHEET!K35) | M34: =IF(DATASHEET!L35=0,"",DATASHEET!L35) | N34: =J34-G34 -> 16 | O34: =IF(M34="",$H34,M34) -> 27.94 | P34: =IF(ISERROR($H34-M34),0,ABS($H34-M34)) -> 0 | Q34: 1 | R34: =IF(K34="Y",1,0) -> 0 | S34: =IF(L34="Y",1,0) -> 0 | T34: =IF(DATASHEET!M35=0,"",DATASHEET!M35) -> 42157 | U34: =IF(DATASHEET!N35=0,"",DATASHEET!N35) | V34: =IF(DATASHEET!O35=0,"",DATASHEET!O35) | W34: =IF(DATASHEET!Q35=0,"",DATASHEET!Q35) -> 40.386 | X34: =T34-$G34 -> 56 | Y34: =W34 -> 40.386 | Z34: =IF(AND($H34-W34>0,U34="Y"),ABS($H34-W34),0) -> 0 | AA34: 1 | AB34: =IF(U34="Y",1,0) -> 0 | AC34: =IF(V34="Y",1,0) -> 0 | AD34: =IF(DATASHEET!R35=0,"",DATASHEET!R35) -> 42233 | AE34: =IF(DATASHEET!S35=0,"",DATASHEET!S35) | AF34: =IF(DATASHEET!T35=0,"",DATASHEET!T35) -> Y | AG34: =IF(DATASHEET!V35=0,"",DATASHEET!V35) -> 44 | AH34: =AD34-$G34 -> 132 | AI34: =AG34 -> 44 | AJ34: =IF(AND($W34-AG34>0,AE34="Y"),ABS($W34-AG34),0) -> 0 | AK34: 1 | AL34: =IF(AE34="Y",1,0) -> 0 | AM34: =IF(AF34="Y",1,0) -> 1 | AN34: =IF(DATASHEET!X35=0,"",DATASHEET!X35) | AO34: =IF(DATASHEET!Y35=0,"",DATASHEET!Y35) | AP34: =IF(DATASHEET!Z35=0,"",DATASHEET!Z35) | AQ34: =IF(DATASHEET!AA35=0,"",DATASHEET!AA35) | AR34: =IF(DATASHEET!AB35=0,"",DATASHEET!AB35) | AS34: =IF(DATASHEET!AC35=0,"",DATASHEET!AC35) | AT34: =IF(DATASHEET!AD35=0,"",DATASHEET!AD35) | AU34: =IF(DATASHEET!AE35=0,"",DATASHEET!AE35)
A35: =IF(DATASHEET!A36=0,"",DATASHEET!A36) -> HUMANN RESOURCES 2010 | B35: =IF(DATASHEET!B36=0,"",DATASHEET!B36) -> B | C35: =IF(DATASHEET!C36=0,"",DATASHEET!C36) -> PLANTSKYDD | D35: =IF(C35="CO-PLANTING",CONCATENATE(C35," ",F35),C35) -> PLANTSKYDD | E35: =IF(DATASHEET!D36=0,"",DATASHEET!D36) -> 13 | F35: =IF(DATASHEET!E36=0,"",DATASHEET!E36) -> WRC | G35: =IF(DATASHEET!F36=0,"",DATASHEET!F36) -> 42101 | H35: =IF(DATASHEET!G36=0,"",DATASHEET!G36) -> 28.956 | I35: =IF(DATASHEET!H36=0,"",DATASHEET!H36) -> 3.302 | J35: =IF(DATASHEET!I36=0,"",DATASHEET!I36) -> 42117 | K35: =IF(DATASHEET!J36=0,"",DATASHEET!J36) | L35: =IF(DATASHEET!K36=0,"",DATASHEET!K36) | M35: =IF(DATASHEET!L36=0,"",DATASHEET!L36) | N35: =J35-G35 -> 16 | O35: =IF(M35="",$H35,M35) -> 28.956 | P35: =IF(ISERROR($H35-M35),0,ABS($H35-M35)) -> 0 | Q35: 1 | R35: =IF(K35="Y",1,0) -> 0 | S35: =IF(L35="Y",1,0) -> 0 | T35: =IF(DATASHEET!M36=0,"",DATASHEET!M36) -> 42157 | U35: =IF(DATASHEET!N36=0,"",DATASHEET!N36) | V35: =IF(DATASHEET!O36=0,"",DATASHEET!O36) | W35: =IF(DATASHEET!Q36=0,"",DATASHEET!Q36) -> 40.894 | X35: =T35-$G35 -> 56 | Y35: =W35 -> 40.894 | Z35: =IF(AND($H35-W35>0,U35="Y"),ABS($H35-W35),0) -> 0 | AA35: 1 | AB35: =IF(U35="Y",1,0) -> 0 | AC35: =IF(V35="Y",1,0) -> 0 | AD35: =IF(DATASHEET!R36=0,"",DATASHEET!R36) -> 42233 | AE35: =IF(DATASHEET!S36=0,"",DATASHEET!S36) | AF35: =IF(DATASHEET!T36=0,"",DATASHEET!T36) -> Y | AG35: =IF(DATASHEET!V36=0,"",DATASHEET!V36) -> 45 | AH35: =AD35-$G35 -> 132 | AI35: =AG35 -> 45 | AJ35: =IF(AND($W35-AG35>0,AE35="Y"),ABS($W35-AG35),0) -> 0 | AK35: 1 | AL35: =IF(AE35="Y",1,0) -> 0 | AM35: =IF(AF35="Y",1,0) -> 1 | AN35: =IF(DATASHEET!X36=0,"",DATASHEET!X36) | AO35: =IF(DATASHEET!Y36=0,"",DATASHEET!Y36) | AP35: =IF(DATASHEET!Z36=0,"",DATASHEET!Z36) | AQ35: =IF(DATASHEET!AA36=0,"",DATASHEET!AA36) | AR35: =IF(DATASHEET!AB36=0,"",DATASHEET!AB36) | AS35: =IF(DATASHEET!AC36=0,"",DATASHEET!AC36) | AT35: =IF(DATASHEET!AD36=0,"",DATASHEET!AD36) | AU35: =IF(DATASHEET!AE36=0,"",DATASHEET!AE36)
A36: =IF(DATASHEET!A37=0,"",DATASHEET!A37) -> HUMANN RESOURCES 2010 | B36: =IF(DATASHEET!B37=0,"",DATASHEET!B37) -> B | C36: =IF(DATASHEET!C37=0,"",DATASHEET!C37) -> PLANTSKYDD | D36: =IF(C36="CO-PLANTING",CONCATENATE(C36," ",F36),C36) -> PLANTSKYDD | E36: =IF(DATASHEET!D37=0,"",DATASHEET!D37) -> 14 | F36: =IF(DATASHEET!E37=0,"",DATASHEET!E37) -> WRC | G36: =IF(DATASHEET!F37=0,"",DATASHEET!F37) -> 42101 | H36: =IF(DATASHEET!G37=0,"",DATASHEET!G37) -> 24.638 | I36: =IF(DATASHEET!H37=0,"",DATASHEET!H37) -> 2.286 | J36: =IF(DATASHEET!I37=0,"",DATASHEET!I37) -> 42117 | K36: =IF(DATASHEET!J37=0,"",DATASHEET!J37) | L36: =IF(DATASHEET!K37=0,"",DATASHEET!K37) | M36: =IF(DATASHEET!L37=0,"",DATASHEET!L37) | N36: =J36-G36 -> 16 | O36: =IF(M36="",$H36,M36) -> 24.638 | P36: =IF(ISERROR($H36-M36),0,ABS($H36-M36)) -> 0 | Q36: 1 | R36: =IF(K36="Y",1,0) -> 0 | S36: =IF(L36="Y",1,0) -> 0 | T36: =IF(DATASHEET!M37=0,"",DATASHEET!M37) -> 42157 | U36: =IF(DATASHEET!N37=0,"",DATASHEET!N37) | V36: =IF(DATASHEET!O37=0,"",DATASHEET!O37) | W36: =IF(DATASHEET!Q37=0,"",DATASHEET!Q37) -> 23.368 | X36: =T36-$G36 -> 56 | Y36: =W36 -> 23.368 | Z36: =IF(AND($H36-W36>0,U36="Y"),ABS($H36-W36),0) -> 0 | AA36: 1 | AB36: =IF(U36="Y",1,0) -> 0 | AC36: =IF(V36="Y",1,0) -> 0 | AD36: =IF(DATASHEET!R37=0,"",DATASHEET!R37) -> 42233 | AE36: =IF(DATASHEET!S37=0,"",DATASHEET!S37) | AF36: =IF(DATASHEET!T37=0,"",DATASHEET!T37) -> Y | AG36: =IF(DATASHEET!V37=0,"",DATASHEET!V37) -> 46 | AH36: =AD36-$G36 -> 132 | AI36: =AG36 -> 46 | AJ36: =IF(AND($W36-AG36>0,AE36="Y"),ABS($W36-AG36),0) -> 0 | AK36: 1 | AL36: =IF(AE36="Y",1,0) -> 0 | AM36: =IF(AF36="Y",1,0) -> 1 | AN36: =IF(DATASHEET!X37=0,"",DATASHEET!X37) | AO36: =IF(DATASHEET!Y37=0,"",DATASHEET!Y37) | AP36: =IF(DATASHEET!Z37=0,"",DATASHEET!Z37) | AQ36: =IF(DATASHEET!AA37=0,"",DATASHEET!AA37) | AR36: =IF(DATASHEET!AB37=0,"",DATASHEET!AB37) | AS36: =IF(DATASHEET!AC37=0,"",DATASHEET!AC37) | AT36: =IF(DATASHEET!AD37=0,"",DATASHEET!AD37) | AU36: =IF(DATASHEET!AE37=0,"",DATASHEET!AE37)
A37: =IF(DATASHEET!A38=0,"",DATASHEET!A38) -> HUMANN RESOURCES 2010 | B37: =IF(DATASHEET!B38=0,"",DATASHEET!B38) -> B | C37: =IF(DATASHEET!C38=0,"",DATASHEET!C38) -> PLANTSKYDD | D37: =IF(C37="CO-PLANTING",CONCATENATE(C37," ",F37),C37) -> PLANTSKYDD | E37: =IF(DATASHEET!D38=0,"",DATASHEET!D38) -> 15 | F37: =IF(DATASHEET!E38=0,"",DATASHEET!E38) -> WRC | G37: =IF(DATASHEET!F38=0,"",DATASHEET!F38) -> 42101 | H37: =IF(DATASHEET!G38=0,"",DATASHEET!G38) -> 25.4 | I37: =IF(DATASHEET!H38=0,"",DATASHEET!H38) -> 2.286 | J37: =IF(DATASHEET!I38=0,"",DATASHEET!I38) -> 42117 | K37: =IF(DATASHEET!J38=0,"",DATASHEET!J38) | L37: =IF(DATASHEET!K38=0,"",DATASHEET!K38) | M37: =IF(DATASHEET!L38=0,"",DATASHEET!L38) | N37: =J37-G37 -> 16 | O37: =IF(M37="",$H37,M37) -> 25.4 | P37: =IF(ISERROR($H37-M37),0,ABS($H37-M37)) -> 0 | Q37: 1 | R37: =IF(K37="Y",1,0) -> 0 | S37: =IF(L37="Y",1,0) -> 0 | T37: =IF(DATASHEET!M38=0,"",DATASHEET!M38) -> 42157 | U37: =IF(DATASHEET!N38=0,"",DATASHEET!N38) | V37: =IF(DATASHEET!O38=0,"",DATASHEET!O38) | W37: =IF(DATASHEET!Q38=0,"",DATASHEET!Q38) -> 27.686 | X37: =T37-$G37 -> 56 | Y37: =W37 -> 27.686 | Z37: =IF(AND($H37-W37>0,U37="Y"),ABS($H37-W37),0) -> 0 | AA37: 1 | AB37: =IF(U37="Y",1,0) -> 0 | AC37: =IF(V37="Y",1,0) -> 0 | AD37: =IF(DATASHEET!R38=0,"",DATASHEET!R38) -> 42233 | AE37: =IF(DATASHEET!S38=0,"",DATASHEET!S38) | AF37: =IF(DATASHEET!T38=0,"",DATASHEET!T38) -> Y | AG37: =IF(DATASHEET!V38=0,"",DATASHEET!V38) -> 30.5 | AH37: =AD37-$G37 -> 132 | AI37: =AG37 -> 30.5 | AJ37: =IF(AND($W37-AG37>0,AE37="Y"),ABS($W37-AG37),0) -> 0 | AK37: 1 | AL37: =IF(AE37="Y",1,0) -> 0 | AM37: =IF(AF37="Y",1,0) -> 1 | AN37: =IF(DATASHEET!X38=0,"",DATASHEET!X38) | AO37: =IF(DATASHEET!Y38=0,"",DATASHEET!Y38) | AP37: =IF(DATASHEET!Z38=0,"",DATASHEET!Z38) | AQ37: =IF(DATASHEET!AA38=0,"",DATASHEET!AA38) | AR37: =IF(DATASHEET!AB38=0,"",DATASHEET!AB38) | AS37: =IF(DATASHEET!AC38=0,"",DATASHEET!AC38) | AT37: =IF(DATASHEET!AD38=0,"",DATASHEET!AD38) | AU37: =IF(DATASHEET!AE38=0,"",DATASHEET!AE38)
A38: =IF(DATASHEET!A39=0,"",DATASHEET!A39) -> HUMANN RESOURCES 2010 | B38: =IF(DATASHEET!B39=0,"",DATASHEET!B39) -> B | C38: =IF(DATASHEET!C39=0,"",DATASHEET!C39) -> PLANTSKYDD | D38: =IF(C38="CO-PLANTING",CONCATENATE(C38," ",F38),C38) -> PLANTSKYDD | E38: =IF(DATASHEET!D39=0,"",DATASHEET!D39) -> 16 | F38: =IF(DATASHEET!E39=0,"",DATASHEET!E39) -> WRC | G38: =IF(DATASHEET!F39=0,"",DATASHEET!F39) -> 42101 | H38: =IF(DATASHEET!G39=0,"",DATASHEET!G39) -> 27.178 | I38: =IF(DATASHEET!H39=0,"",DATASHEET!H39) -> 3.302 | J38: =IF(DATASHEET!I39=0,"",DATASHEET!I39) -> 42117 | K38: =IF(DATASHEET!J39=0,"",DATASHEET!J39) | L38: =IF(DATASHEET!K39=0,"",DATASHEET!K39) | M38: =IF(DATASHEET!L39=0,"",DATASHEET!L39) | N38: =J38-G38 -> 16 | O38: =IF(M38="",$H38,M38) -> 27.178 | P38: =IF(ISERROR($H38-M38),0,ABS($H38-M38)) -> 0 | Q38: 1 | R38: =IF(K38="Y",1,0) -> 0 | S38: =IF(L38="Y",1,0) -> 0 | T38: =IF(DATASHEET!M39=0,"",DATASHEET!M39) -> 42157 | U38: =IF(DATASHEET!N39=0,"",DATASHEET!N39) | V38: =IF(DATASHEET!O39=0,"",DATASHEET!O39) | W38: =IF(DATASHEET!Q39=0,"",DATASHEET!Q39) -> 31.242 | X38: =T38-$G38 -> 56 | Y38: =W38 -> 31.242 | Z38: =IF(AND($H38-W38>0,U38="Y"),ABS($H38-W38),0) -> 0 | AA38: 1 | AB38: =IF(U38="Y",1,0) -> 0 | AC38: =IF(V38="Y",1,0) -> 0 | AD38: =IF(DATASHEET!R39=0,"",DATASHEET!R39) -> 42233 | AE38: =IF(DATASHEET!S39=0,"",DATASHEET!S39) | AF38: =IF(DATASHEET!T39=0,"",DATASHEET!T39) -> Y | AG38: =IF(DATASHEET!V39=0,"",DATASHEET!V39) | AH38: =AD38-$G38 -> 132 | AI38: =AG38 | AK38: 1 | AL38: =IF(AE38="Y",1,0) -> 0 | AM38: =IF(AF38="Y",1,0) -> 1 | AN38: =IF(DATASHEET!X39=0,"",DATASHEET!X39) | AO38: =IF(DATASHEET!Y39=0,"",DATASHEET!Y39) | AP38: =IF(DATASHEET!Z39=0,"",DATASHEET!Z39) | AQ38: =IF(DATASHEET!AA39=0,"",DATASHEET!AA39) | AR38: =IF(DATASHEET!AB39=0,"",DATASHEET!AB39) | AS38: =IF(DATASHEET!AC39=0,"",DATASHEET!AC39) | AT38: =IF(DATASHEET!AD39=0,"",DATASHEET!AD39) | AU38: =IF(DATASHEET!AE39=0,"",DATASHEET!AE39)
A39: =IF(DATASHEET!A40=0,"",DATASHEET!A40) -> HUMANN RESOURCES 2010 | B39: =IF(DATASHEET!B40=0,"",DATASHEET!B40) -> B | C39: =IF(DATASHEET!C40=0,"",DATASHEET!C40) -> PLANTSKYDD | D39: =IF(C39="CO-PLANTING",CONCATENATE(C39," ",F39),C39) -> PLANTSKYDD | E39: =IF(DATASHEET!D40=0,"",DATASHEET!D40) -> 17 | F39: =IF(DATASHEET!E40=0,"",DATASHEET!E40) -> WRC | G39: =IF(DATASHEET!F40=0,"",DATASHEET!F40) -> 42101 | H39: =IF(DATASHEET!G40=0,"",DATASHEET!G40) -> 22.86 | I39: =IF(DATASHEET!H40=0,"",DATASHEET!H40) -> 2.286 | J39: =IF(DATASHEET!I40=0,"",DATASHEET!I40) -> 42117 | K39: =IF(DATASHEET!J40=0,"",DATASHEET!J40) | L39: =IF(DATASHEET!K40=0,"",DATASHEET!K40) | M39: =IF(DATASHEET!L40=0,"",DATASHEET!L40) | N39: =J39-G39 -> 16 | O39: =IF(M39="",$H39,M39) -> 22.86 | P39: =IF(ISERROR($H39-M39),0,ABS($H39-M39)) -> 0 | Q39: 1 | R39: =IF(K39="Y",1,0) -> 0 | S39: =IF(L39="Y",1,0) -> 0 | T39: =IF(DATASHEET!M40=0,"",DATASHEET!M40) -> 42157 | U39: =IF(DATASHEET!N40=0,"",DATASHEET!N40) | V39: =IF(DATASHEET!O40=0,"",DATASHEET!O40) | W39: =IF(DATASHEET!Q40=0,"",DATASHEET!Q40) -> 25.4 | X39: =T39-$G39 -> 56 | Y39: =W39 -> 25.4 | Z39: =IF(AND($H39-W39>0,U39="Y"),ABS($H39-W39),0) -> 0 | AA39: 1 | AB39: =IF(U39="Y",1,0) -> 0 | AC39: =IF(V39="Y",1,0) -> 0 | AD39: =IF(DATASHEET!R40=0,"",DATASHEET!R40) -> 42233 | AE39: =IF(DATASHEET!S40=0,"",DATASHEET!S40) | AF39: =IF(DATASHEET!T40=0,"",DATASHEET!T40) -> Y | AG39: =IF(DATASHEET!V40=0,"",DATASHEET!V40) -> 26 | AH39: =AD39-$G39 -> 132 | AI39: =AG39 -> 26 | AJ39: =IF(AND($W39-AG39>0,AE39="Y"),ABS($W39-AG39),0) -> 0 | AK39: 1 | AL39: =IF(AE39="Y",1,0) -> 0 | AM39: =IF(AF39="Y",1,0) -> 1 | AN39: =IF(DATASHEET!X40=0,"",DATASHEET!X40) | AO39: =IF(DATASHEET!Y40=0,"",DATASHEET!Y40) | AP39: =IF(DATASHEET!Z40=0,"",DATASHEET!Z40) | AQ39: =IF(DATASHEET!AA40=0,"",DATASHEET!AA40) | AR39: =IF(DATASHEET!AB40=0,"",DATASHEET!AB40) | AS39: =IF(DATASHEET!AC40=0,"",DATASHEET!AC40) | AT39: =IF(DATASHEET!AD40=0,"",DATASHEET!AD40) | AU39: =IF(DATASHEET!AE40=0,"",DATASHEET!AE40)
A40: =IF(DATASHEET!A41=0,"",DATASHEET!A41) -> HUMANN RESOURCES 2010 | B40: =IF(DATASHEET!B41=0,"",DATASHEET!B41) -> B | C40: =IF(DATASHEET!C41=0,"",DATASHEET!C41) -> PLANTSKYDD | D40: =IF(C40="CO-PLANTING",CONCATENATE(C40," ",F40),C40) -> PLANTSKYDD | E40: =IF(DATASHEET!D41=0,"",DATASHEET!D41) -> 18 | F40: =IF(DATASHEET!E41=0,"",DATASHEET!E41) -> WRC | G40: =IF(DATASHEET!F41=0,"",DATASHEET!F41) -> 42101 | H40: =IF(DATASHEET!G41=0,"",DATASHEET!G41) -> 23.876 | I40: =IF(DATASHEET!H41=0,"",DATASHEET!H41) -> 2.794 | J40: =IF(DATASHEET!I41=0,"",DATASHEET!I41) -> 42117 | K40: =IF(DATASHEET!J41=0,"",DATASHEET!J41) | L40: =IF(DATASHEET!K41=0,"",DATASHEET!K41) | M40: =IF(DATASHEET!L41=0,"",DATASHEET!L41) | N40: =J40-G40 -> 16 | O40: =IF(M40="",$H40,M40) -> 23.876 | P40: =IF(ISERROR($H40-M40),0,ABS($H40-M40)) -> 0 | Q40: 1 | R40: =IF(K40="Y",1,0) -> 0 | S40: =IF(L40="Y",1,0) -> 0 | T40: =IF(DATASHEET!M41=0,"",DATASHEET!M41) -> 42157 | U40: =IF(DATASHEET!N41=0,"",DATASHEET!N41) | V40: =IF(DATASHEET!O41=0,"",DATASHEET!O41) | W40: =IF(DATASHEET!Q41=0,"",DATASHEET!Q41) -> 30.226 | X40: =T40-$G40 -> 56 | Y40: =W40 -> 30.226 | Z40: =IF(AND($H40-W40>0,U40="Y"),ABS($H40-W40),0) -> 0 | AA40: 1 | AB40: =IF(U40="Y",1,0) -> 0 | AC40: =IF(V40="Y",1,0) -> 0 | AD40: =IF(DATASHEET!R41=0,"",DATASHEET!R41) -> 42233 | AE40: =IF(DATASHEET!S41=0,"",DATASHEET!S41) | AF40: =IF(DATASHEET!T41=0,"",DATASHEET!T41) -> Y | AG40: =IF(DATASHEET!V41=0,"",DATASHEET!V41) -> 33 | AH40: =AD40-$G40 -> 132 | AI40: =AG40 -> 33 | AJ40: =IF(AND($W40-AG40>0,AE40="Y"),ABS($W40-AG40),0) -> 0 | AK40: 1 | AL40: =IF(AE40="Y",1,0) -> 0 | AM40: =IF(AF40="Y",1,0) -> 1 | AN40: =IF(DATASHEET!X41=0,"",DATASHEET!X41) | AO40: =IF(DATASHEET!Y41=0,"",DATASHEET!Y41) | AP40: =IF(DATASHEET!Z41=0,"",DATASHEET!Z41) | AQ40: =IF(DATASHEET!AA41=0,"",DATASHEET!AA41) | AR40: =IF(DATASHEET!AB41=0,"",DATASHEET!AB41) | AS40: =IF(DATASHEET!AC41=0,"",DATASHEET!AC41) | AT40: =IF(DATASHEET!AD41=0,"",DATASHEET!AD41) | AU40: =IF(DATASHEET!AE41=0,"",DATASHEET!AE41)
